Workbook

Sheet Гипотеза T
B2: А. Гипотеза. Digital канал + Биллинг Т | H2: B. Гипотеза. Sales канал Т + Биллинг Т | N2: С. Гипотеза. Sales канал MPS + Биллинг Т | T2: D. Гипотеза. Sales канал MPS + Биллинг MPS | Z2: E. Гипотеза. Digital + Sales канал MPS + Биллинг Т | AF2: F. Гипотеза. Digital + Sales канал Т + Биллинг Т
A3: Воронка | B3: Переменные | C3: Сегмент 1. Активные клиенты в Т с выплатами от МП. 1 приоритет | D3: Сегмент 2. Активные клиенты в Т., но без выплат от МП | E3: Сегмент 3. Спящие клиенты в Т (нет транзакций по РКО) | F3: Сегмент 4. Клиенты без РКО в Т - Рынок | G3: Все сегменты | H3: Переменные | I3: Сегмент 1. Активные клиенты в Т с выплатами от МП. 1 приоритет | J3: Сегмент 2. Активные клиенты в Т., но без выплат от МП | K3: Сегмент 3. Спящие клиенты в Т (нет транзакций по РКО) | L3: Сегмент 4. Клиенты без РКО в Т - Рынок | M3: Все сегменты | N3: Переменные | O3: Сегмент 1. Активные клиенты в Т с выплатами от МП. 1 приоритет | P3: Сегмент 2. Активные клиенты в Т., но без выплат от МП | Q3: Сегмент 3. Спящие клиенты в Т (нет транзакций по РКО) | R3: Сегмент 4. Клиенты без РКО в Т - Рынок | S3: Все сегменты | T3: Переменные | U3: Сегмент 1. Активные клиенты в Т с выплатами от МП. 1 приоритет | V3: Сегмент 2. Активные клиенты в Т., но без выплат от МП на РКО | W3: Сегмент 3. Спящие клиенты в Т (нет транзакций по РКО) | X3: Сегмент 4. Клиенты без РКО в Т - Рынок | Y3: Все сегменты | Z3: Переменные | AA3: Сегмент 1. Активные клиенты в Т с выплатами от МП. 1 приоритет | AB3: Сегмент 2. Активные клиенты в Т., но без выплат от МП на РКО | AC3: Сегмент 3. Спящие клиенты в Т (нет транзакций по РКО) | AD3: Сегмент 4. Клиенты без РКО в Т - Рынок | AE3: Все сегменты | AF3: Переменные | AG3: Сегмент 1. Активные клиенты в Т с выплатами от МП. 1 приоритет | AH3: Сегмент 2. Активные клиенты в Т., но без выплат от МП на РКО | AI3: Сегмент 3. Спящие клиенты в Т (нет транзакций по РКО) | AJ3: Сегмент 4. Клиенты без РКО в Т - Рынок | AK3: Все сегменты
A4: База селлеров | C4: =Переменные!B9 -> 79000 | D4: =Переменные!C9 -> 33000 | E4: =Переменные!D9 -> 13000 | F4: =Переменные!E9 -> 247000 | G4: =Переменные!F9 -> 372000 | I4: =C4 -> 79000 | J4: =D4 -> 33000 | K4: =E4 -> 13000 | L4: =F4 -> 247000 | M4: =G4 -> 372000 | O4: =I4 -> 79000 | P4: =J4 -> 33000 | Q4: =K4 -> 13000 | R4: =L4 -> 247000 | S4: =M4 -> 372000
A5: Лиды (первое посещение Селлера) | C5: =C4 -> 79000 | D5: =D4 -> 33000 | E5: =E4 -> 13000 | F5: =F4 -> 247000 | G5: =G4 -> 372000 | I5: =I4 -> 79000 | J5: =J4 -> 33000 | K5: =K4 -> 13000 | L5: =L4 -> 247000 | M5: =M4 -> 372000 | O5: =O4 -> 79000 | P5: =P4 -> 33000 | Q5: =Q4 -> 13000 | R5: =R4 -> 247000 | S5: =S4 -> 372000
A6: Оффер триала
A7: Триала выдан
A8: Активация триала
A9: Оставление API ключа
A10: Активация в Селлере
A11: Квалификация лидов (звонок КЦ) - ЦА
A12: Оффер демо встречи
A13: Согласились на демо встречу
A14: Демо встреча состоялась
A15: Дозвон sales (продажа без демо)
A16: Оплата тарифа первая покупка | C16: 1 | D16: 2
A17: Повторные покупки | B17: +50% оплат c картотек | H17: +50% оплат c картотек
A20: Доход от первых покупок | C20: =C16*C40 -> 12400 | D20: =D16*D40 -> 24800 | E20: =E16*E40 -> 0 | F20: =F16*F40 -> 0 | G20: =G16*G40 -> 0
A21: Через какое время
A23: LTV (тарифы) | C23: =SUM(C25:C27) -> 24282.486 | D23: =SUM(D25:D27) -> 50438.485 | E23: =SUM(E25:E27) -> 0 | F23: =SUM(F25:F27) -> 0 | G23: =SUM(G25:G27) -> 0
A24: LTV по сегментам
A25: 10 + млн | C25: =C$16*C51*C58 -> 505.54737 | D25: =D$16*D51*D58 -> 2561.6466 | E25: =E$16*E51*E58 -> 0 | F25: =F$16*F51*F58 -> 0 | G25: =G$16*G51*G58 -> 0
A26: 1-10 млн | C26: =C$16*C52*C59 -> 3923.9742 | D26: =D$16*D52*D59 -> 10409.723 | E26: =E$16*E52*E59 -> 0 | F26: =F$16*F52*F59 -> 0 | G26: =G$16*G52*G59 -> 0
A27: менее 1 млн | C27: =C$16*C53*C60 -> 19852.965 | D27: =D$16*D53*D60 -> 37467.115 | E27: =E$16*E53*E60 -> 0 | F27: =F$16*F53*F60 -> 0 | G27: =G$16*G53*G60 -> 0
A29: Через какое время
A30: LTV (другие продукты Банка) | C30: =Переменные!$C$79*'Гипотеза T'!C16 -> 40000 | D30: =Переменные!$C$79*'Гипотеза T'!D16 -> 80000 | E30: =Переменные!$C$79*'Гипотеза T'!E16 -> 0 | F30: =Переменные!$C$79*'Гипотеза T'!F16 -> 0 | G30: =Переменные!$C$79*'Гипотеза T'!G16 -> 0
A32: Расход на 1 клиента | B32: Карина? | H32: Карина? | N32: MPS? | T32: MPS? | Z32: MPS? | AF32: Карина?
A33: Привлечение (sales) | B33: Карина? | H33: Карина? | N33: MPS? | T33: MPS? | Z33: MPS? | AF33: Карина?
A34: Содержание (триал, поддрежка) | B34: Карина? | H34: Карина? | N34: MPS? | T34: MPS? | Z34: MPS? | AF34: Карина?
A39: Дополнительные данные для расчета
A40: Ср чек первой покупки | C40: =Переменные!D51 -> 12400 | D40: =C40 -> 12400 | E40: =D40 -> 12400 | F40: =E40 -> 12400 | G40: =F40 -> 12400
A41: Ср чек первой покупки по сегментам
A42: 10 + млн | C42: MPS? | D42: MPS? | E42: MPS? | F42: MPS? | G42: MPS?
A43: 1-10 млн | C43: MPS? | D43: MPS? | E43: MPS? | F43: MPS? | G43: MPS?
A44: менее 1 млн | C44: MPS? | D44: MPS? | E44: MPS? | F44: MPS? | G44: MPS?
A45: Unk | C45: MPS? | D45: MPS? | E45: MPS? | F45: MPS? | G45: MPS?
A47: Ср время от лида до первой покупки
A48: CR повторной покупки
A50: Распределение кол-ва селлеров по сегментам по оборотам в Т-Банке
A51: 10 + млн | C51: =Переменные!B25 -> 0.0086944479 | D51: =Переменные!C25 -> 0.022027711 | E51: =Переменные!D25 -> 0.014373426 | F51: =Переменные!E25 -> 0.014373426 | G51: =Переменные!G25 -> 0.014373426
A52: 1-10 млн | C52: =Переменные!B26 -> 0.11118121 | D52: =Переменные!C26 -> 0.14747366 | E52: =Переменные!D26 -> 0.12663987 | F52: =Переменные!E26 -> 0.12663987 | G52: =Переменные!G26 -> 0.12663987
...

Sheet Вопросы
A1: Вопросы
A3: Воронка DIGITAL | B3: Точно ли конверсии коррекные? | C3: Саша | D3: https://jira.tcsbank.ru/browse/ECA-2046
B4: средний срок жизни платного клиента , ltv, | C4: Саша
B5: факт прохождения триала - можно глянуть сколько % совершают ЦД в рамках триала (и мб ограничить платными фичами) - влияет на расходы
A6: Воронка SALES | B6: Когда сможем построить? | C6: Саша | D6: https://jira.tcsbank.ru/browse/ECA-2046
A7: Т-банк | B7: Сколько дают картотеки? Гипотеза | C7: Юля/Саша
A8: MPST | B8: Как посчитать конверсию MPS сквозную от квалив лидов | C8: Юля
B9: LTV по сегментам - дозревший? | C9: MPS
B10: Ср чек первой покупки - есть общий без сегментации | C10: MPS
B11: Ср чек первой покупки (по сегментам) и Ср время до первой покупки - какой доход получим за X времени? | C11: MPS
B12: Ретеншн (по сегментам) - за какое время получим доход? | C12: MPS
B13: Расходы на привлечение (sales, КЦ) | C13: MPS
B14: Расходы на содержание (триал, поддержка) | C14: MPS
B15: Пересечение баз - какой базе продаем, какие сегменты - какие тарифы (за вычетом пересечений баз: есть тариф - исключаем, есть апи и нет тарифа - низкая вреоятность покупки) | C15: Карина/ MPS
A16: Т-банк | B16: Расходы на привлечение (sales, КЦ) | C16: Карина
A17: Т-банк | B17: Расходы на содержание (триал, поддержка) | C17: Карина
A20: Флоу | B20: Триал - сейчас доступен без АПИ? | C20: Юля
A21: Флоу | B21: В воронке имеет сымсл оставлять сначала АПИ потом триал иначе будут оставлять в МПСтатс, наша база для для Селелр и ОБ не будет пополняться как раньше | C21: Юля
B25: Измененеи мтерик
B26: Навигация - подключился? Видел? | C26: Саша | D26: https://time.tbank.ru/tinkoff/pl/18hcpdo657s35g9799tcxths91
B27: Онбординг | C27: Саша
B28: Маркетинг | C28: Нина

Sheet Переменные
B1: База селлеров
B2: AS IS
B3: Сегмент по статусу активности
B4: Сегмент 1. Активные клиенты в Т с выплатами от МП. | C4: Сегмент 2. Активные клиенты в Т, но без выплат от МП на РКО | D4: Сегмент 3. Спящие клиенты в Т (нет транзакций по РКО) | E4: Сегмент 4. Клиенты без РКО в Т - Рынок | F4: Все сегменты
B5: 79000 | C5: 33000 | D5: 13000 | E5: 247000 | F5: =SUM(B5:E5) -> 372000
B7: TO BE - убрать пересечение баз с MPS и Точкой
B8: Сегмент 1. Активные клиенты в Т с выплатами от МП. | C8: Сегмент 2. Активные клиенты в Т, но без выплат от МП на РКО | D8: Сегмент 3. Спящие клиенты в Т (нет транзакций по РКО) | E8: Сегмент 4. Клиенты без РКО в Т - Рынок | F8: Все сегменты
B9: =B5 -> 79000 | C9: =C5 -> 33000 | D9: =D5 -> 13000 | E9: =E5 -> 247000 | F9: =F5 -> 372000
B12: Распределение кол-ва селлеров по сегментам по оборотам
B14: Сегмент по статусу активности
A15: Сегмент по обороту | B15: Сегмент 1. Активные клиенты в Т с выплатами от МП. | C15: Сегмент 2. Активные клиенты в Т, но без выплат от МП на РКО | D15: Сегмент 3. Спящие клиенты в Т (нет транзакций по РКО) | E15: Сегмент 4. Клиенты без РКО в Т - Рынок | F15: Все сегменты | G15: Сегмент 1+ Сегмент 2
A16: 10 + млн | B16: 565 | C16: 1062 | D16: ? | E16: ? | F16: ? | G16: 1627
A17: 1-10 млн | B17: 7225 | C17: 7110 | D17: ? | E17: ? | F17: ? | G17: 14335
A18: менее 1 млн | B18: 57194 | C18: 40040 | D18: ? | E18: ? | F18: ? | G18: 97233
A19: Unk | D19: ? | E19: ? | F19: ?
A20: Всего | B20: =SUM(B16:B19) -> 64984 | C20: =SUM(C16:C19) -> 48212 | G20: =SUM(G16:G19) -> 113195
B23: Сегмент по статусу активности
A24: Сегмент по обороту | B24: Сегмент 1. Активные клиенты в Т с выплатами от МП. | C24: Сегмент 2. Активные клиенты в Т, но без выплат от МП на РКО | D24: Сегмент 3. Спящие клиенты в Т (нет транзакций по РКО) | E24: Сегмент 4. Клиенты без РКО в Т - Рынок | F24: Все сегменты | G24: Сегмент 1+ Сегмент 2
A25: 10 + млн | B25: =B16/$B$20 -> 0.0086944479 | C25: =C16/$C$20 -> 0.022027711 | D25: =G25 -> 0.014373426 | E25: =G25 -> 0.014373426 | F25: =G25 -> 0.014373426 | G25: =G16/$G$20 -> 0.014373426
A26: 1-10 млн | B26: =B17/$B$20 -> 0.11118121 | C26: =C17/$C$20 -> 0.14747366 | D26: =G26 -> 0.12663987 | E26: =G26 -> 0.12663987 | F26: =G26 -> 0.12663987 | G26: =G17/$G$20 -> 0.12663987
A27: менее 1 млн | B27: =B18/$B$20 -> 0.88012434 | C27: =C18/$C$20 -> 0.83049863 | D27: =G27 -> 0.8589867 | E27: =G27 -> 0.8589867 | F27: =G27 -> 0.8589867 | G27: =G18/$G$20 -> 0.8589867
A28: Unk | G28: =G19/$G$20 -> 0
B30: LTV MPStats (за май 2025-апрель 2026)
B31: Сегмент по обороту | C31: LTV
B32: 10 + млн | C32: 116292
B33: 1-10 млн | C33: 70587
B34: менее 1 млн | C34: 45114
B35: Unk | C35: 28206
B37: но вероятно это недозревшие данные - тк апр 26
B39: Стоимость тарифов MPStats
B40: AS IS (скидка 50%)
B41: Базовый | C41: Бизнес | D41: Корпоративный
B42: 6495 | C42: 14995 | D42: 34995
B44: TO BE (после согласования с юристами и налоговиками)
B45: Базовый | C45: Бизнес | D45: Корпоративный
B46: =B42 -> 6495 | C46: =C42 -> 14995 | D46: =D42 -> 34995
B48: Ср чек первой покупки
B49: AS IS - MPStats | D49: TO BE - Тбанк (скидка)
B50: 31000 | C50: оптимистично | D50: =B50/2 -> 15500
B51: =0.8*B50 -> 24800 | C51: реалистчно - гипотеза | D51: =B51/2 -> 12400
...

Sheet Воронка MPStats_обработано
D1: Воронка от 1го этапа - лиды | J1: Воронка - от квалиф лида
B2: Воронка | C2: Комментарий к воронке | D2: Mpstats все лиды | E2: Хантеры (демо) | F2: ОТП (звонок, без демо) | G2: Из них: горячие | H2: Из них: заинтересованные | I2: Mpstats Самоходы (оплатили сами без демо и звонка) | J2: Mpstats все лиды | K2: Хантеры (демо) | L2: ОТП (звонок, без демо) | M2: Из них: горячие | N2: Из них: заинтересованные | O2: Mpstats Самоходы (оплатили сами без демо и звонка)
A3: Общий флоу | B3: Лиды (заявка на сайте MPS/ первое посещение Селлера) | D3: 1 | E3: 1 | F3: 1 | G3: - | H3: - | I3: Unk | J3: 1 | K3: 1 | L3: 1 | M3: - | N3: - | O3: Unk
A4: Не считают в воронке | B4: Оффер триала | D4: 1 | E4: 1 | F4: 1 | G4: - | H4: - | I4: Unk | J4: 1 | K4: 1 | L4: 1 | M4: - | N4: - | O4: Unk
B5: Триала выдан | C5: сейчас выдают триал всем автоматом после реги лида | D5: 1 | E5: 1 | F5: 1 | G5: - | H5: - | I5: Unk | J5: 1 | K5: 1 | L5: 1 | M5: - | N5: - | O5: Unk
B6: Активация триала | D6: Unk | E6: Unk | F6: Unk | G6: - | H6: - | I6: Unk | J6: Unk | K6: Unk | L6: Unk | M6: - | N6: - | O6: Unk
B7: Оставление API ключа | D7: Unk | E7: Unk | F7: Unk | G7: - | H7: - | I7: Unk | J7: Unk | K7: Unk | L7: Unk | M7: - | N7: - | O7: Unk
A8: Общий флоу | B8: Квалификация лидов (звонок КЦ) - ЦА | C8: доля Хантеры-40%, ОТП - 60%, Самоходы - Unk | D8: 0.13 | E8: =D10 -> 0.052 | F8: =D8-D10 -> 0.078 | G8: - | H8: - | I8: - | J8: 0.13 | K8: =E8 -> 0.052 | L8: =F8 -> 0.078 | M8: - | N8: - | O8: -
B9: Оффер демо встречи | D9: =D8 -> 0.13 | E9: =E8 -> 0.052 | F9: =F8 -> 0.078 | G9: - | H9: - | I9: - | J9: =J8 -> 0.13 | K9: =K8 -> 0.052 | L9: =L8 -> 0.078 | M9: - | N9: - | O9: -
A10: 1 флоу | B10: Согласились на демо встречу | C10: 40% соглашаются на встречу = Хантеры, 60% не соглашаются = ОТП | D10: =40%*D9 -> 0.052 | E10: =E9 -> 0.052 | F10: 0 | G10: - | H10: - | I10: - | J10: 0.4 | K10: =J10 -> 0.4 | L10: 0 | M10: - | N10: - | O10: -
B11: Демо встреча состоялась | C11: демо состоялось = 29,8% от квалиф. лидов | D11: =E11 -> 0.03874 | E11: =29.8%*D8 -> 0.03874 | F11: 0 | G11: - | H11: - | I11: - | J11: =K11 -> 0.298 | K11: 0.298 | L11: 0 | M11: - | N11: - | O11: -
A12: 2 флоу | B12: Дозвон sales (продажа без демо) | C12: дозвон = 45,5% от квалиф. лидов . Из них: Горячие - доля 15,2% (знают про MPStats, высок. вероятность покупки), Заинтересованные - доля 84,8% (не послали) | D12: =F12 -> 0.05915 | E12: - | F12: =45.5%*D8 -> 0.05915 | G12: =15.2%*F12 -> 0.0089908 | H12: =84.8%*F12 -> 0.0501592 | I12: - | J12: =L12 -> 0.455 | K12: - | L12: 0.455 | M12: =15.2%*L12 -> 0.06916 | N12: =84.8%*L12 -> 0.38584 | O12: -
A13: Общий флоу | B13: Выставлние счета | C13: большая часть продаж - через счет, но есть и для ФЛ способы оплаты. Хантеры: 20% от демо - выставление счета | D13: Unk | E13: =20%*E10 -> 0.0104 | F13: Unk | G13: Unk | H13: Unk | I13: - | J13: Unk | K13: =E13/K8 -> 0.2 | L13: Unk | M13: Unk | N13: Unk | O13: -
B14: Оплата тарифа | C14: Хантеры - 0,7% сквозной СR от лидов; ОТП - 0,41% сквозной СR от лидов или 6,85% от звонка (горячие 34% - от звонка, заинтересован - 2% от звонка) | D14: =E14+F14 -> 0.0111 | E14: 0.007 | F14: 0.0041 | G14: =34%*G12 -> 0.003056872 | H14: =2%*H12 -> 0.001003184 | I14: Unk | J14: =D14/J8 -> 0.085384615 | K14: =E14/K8 -> 0.13461538 | L14: =F14/L8 -> 0.052564103 | M14: =G14/M12 -> 0.0442 | N14: =H14/N12 -> 0.0026 | O14: Unk
A15: Не считают в воронке | B15: Повторная покупка | D15: Unk | E15: Unk | F15: Unk | G15: Unk | H15: Unk | I15: Unk | J15: Unk | K15: Unk | L15: Unk | M15: Unk | N15: Unk | O15: Unk
B19: Дополнительные данные для расчетов
B20: Ср чек первой покупки | C20: 31000 (оптимистично), скорее меньше - 85% | D20: 26350 | J20: 26350
B21: Ср время от лида до первой покупки | D21: Unk | J21: Unk
B23: CR повторной покупки | D23: Unk | J23: Unk
B24: LTV по сегментам по оборотам селеров
B25: 10 + млн | D25: 116292 | J25: 116292
B26: 1-10 млн | D26: 70587 | J26: 70587
B27: менее 1 млн | D27: 45114 | J27: 45114
B28: Unk | D28: 28206 | J28: 28206
B30: Пересечение селлеров Т-Точка-Mpstats | D30: Unk | J30: Unk
B32: Расходы на 1 клиента - привлечение | D32: Unk | J32: Unk
B33: Расходы на 1 клиента - содержание (триал, саппорт) | D33: Unk | J33: Unk

Sheet Воронка MPStats_исх
A1: Воронка продаж: ОТП и Хантеры — средние CR за фев / апр / май 2026
A2: Только CR. Среднее по фев/апр/май (март исключён — акция демо-доступов размыла конверсии; лист сам усредняет эти 3 месяца). Источник цифр — лист «Ретро для июня».
A4: ХАНТЕРЫ (встречи) | B4: СРЕДНЕЕ (Февраль/Апрель/Май)
A5: CR лид → квал | B5: 13%
A6: CR квал → встреча | B6: 29,8%
A7: CR встреча → счёт | B7: 20%
A8: CR счёт → оплата | B8: 90%
A9: Сквозной CR лид → оплата | B9: 0.007
A14: ОТП (звонки) — 2 корзины | B14: СРЕДНЕЕ
A15: CR лид → квал | B15: 13%
A16: CR квал → звонок | B16: 45,5%
A17: доля → корзина ГОРЯЧИЕ | B17: 15,2%
A18: доля → корзина ЗАИНТЕРЕС. | B18: 84,8%
A19: конв. ГОРЯЧИЕ → оплата | B19: 34%
A20: конв. ЗАИНТЕРЕС → оплата | B20: 2%
A21: CR звонок → оплата (итог 2 корзин) | B21: 6,85%
A22: Сквозной CR лид → оплата | B22: 0,41%

Sheet Воронка Селлер as is
A1: Воронка | B1: Комментарий | C1: Селлер Digital канал (с апр25 до апр26) | D1: CR от лидов | E1: Селлер Sales канал (ноя 24-мар25) | F1: CR от лидов
A2: База селлеров Т-Банк | B2: 79- с выплатами от МП на РКО, 33- по внешним данным без выплат на РКО | C2: 113252
A3: Лиды (первое посещение Селлера) | B3: 9200 - MAU, из них селлеров - 5400, первые посещения селлеров - 1300. | C3: 1300
A4: Оставление API ключа | B4: 900 - первые оставления АПИ. Почему высокий CR АПИ? Ср за янв-май 2026 по отчету - 14,1% (302) | C4: 900 | D4: =C4/C3 -> 0.69230769
A5: Активация | B5: Ср за янв-май 2026 по отчету - 15,1% (317)
A6: Оффер триала | B6: триал доступен всем | C6: Unk
A7: Триал выдан | C7: Unk
A8: Триал активирован | B8: нет четких криериев активации тариал, но модно посмотрать факт ЦД во время триала | C8: Unk
A9: Оффер демо встречи | C9: -
A10: Согласились на демо встречу | C10: -
A11: Демо встреча состоялась | C11: -
A12: Оплата тарифа | B12: покупка в рамках окончания триала -110. Это корректные конверсии? | C12: 110 | D12: =C12/C3 -> 0.084615385
A13: Допродажа платного тарифа | B13: покупка без триала / по окончанию триала отключили и купили позже -100. Это корректные конверсии? | C13: 100 | D13: =C13/C3 -> 0.076923077
A14: Оплата тарифа всего | C14: =C13+C12 -> 210 | D14: =C14/C3 -> 0.16153846
A15: Повторные покупки | B15: почему больше чем первичные покупки? Тк это усредненные | C15: 238
A17: Дополнительные данные для расчетов
B18: CR в покупку тарифов
B19: фин аналитика/ отзывы 3000 р | C19: 0.6
B20: ИУ месячный М тариф 3000 р | C20: 0.51
B21: М тариф 10000 р - до сент 25 (после только ИУ 3000) | C21: 0.25
B23: LTV | C23: Unk
B24: Ср срок жизни клиента/ретеншн подписки | C24: Unk

Sheet Селлер_исх
B1: Гранулярность | C1: CR API | D1: CR Активация | E1: CR Налоги | F1: CR Себестоимость | I1: Гранулярность | J1: API | K1: Активации | L1: Налоги | M1: Реги | N1: Себестоимость
A2: 0 | B2: 44896 | C2: 0.52317328 | D2: 0.47494781 | E2: 0 | F2: 0 | H2: 0 | I2: 44896 | J2: 2506 | K2: 2275 | L2: 0 | M2: 4790 | N2: 0
A3: 1 | B3: 44927 | C3: 0.4847352 | D3: 0.42866044 | E3: 0 | F3: 0 | H3: 1 | I3: 44927 | J3: 778 | K3: 688 | L3: 0 | M3: 1605 | N3: 0
A4: 2 | B4: 44958 | C4: 0.49058296 | D4: 0.42959641 | E4: 0 | F4: 0 | H4: 2 | I4: 44958 | J4: 547 | K4: 479 | L4: 0 | M4: 1115 | N4: 0
A5: 3 | B5: 44986 | C5: 0.40740741 | D5: 0.27805417 | E5: 0 | F5: 0 | H5: 3 | I5: 44986 | J5: 737 | K5: 503 | L5: 0 | M5: 1809 | N5: 0
A6: 4 | B6: 45017 | C6: 0.34640811 | D6: 0.21507272 | E6: 0 | F6: 0 | H6: 4 | I6: 45017 | J6: 786 | K6: 488 | L6: 0 | M6: 2269 | N6: 0
A7: 5 | B7: 45047 | C7: 0.29070691 | D7: 0.18506751 | E7: 0 | F7: 0 | H7: 5 | I7: 45047 | J7: 366 | K7: 233 | L7: 0 | M7: 1259 | N7: 0
A8: 6 | B8: 45078 | C8: 0.31122089 | D8: 0.24841214 | E8: 0 | F8: 0 | H8: 6 | I8: 45078 | J8: 441 | K8: 352 | L8: 0 | M8: 1417 | N8: 0
A9: 7 | B9: 45108 | C9: 0.31468531 | D9: 0.39429801 | E9: 0 | F9: 0 | H9: 7 | I9: 45108 | J9: 585 | K9: 733 | L9: 0 | M9: 1859 | N9: 0
A10: 8 | B10: 45139 | C10: 0.27371274 | D10: 0.36720867 | E10: 0 | F10: 0.013098464 | H10: 8 | I10: 45139 | J10: 606 | K10: 813 | L10: 0 | M10: 2214 | N10: 29
A11: 9 | B11: 45170 | C11: 0.24294961 | D11: 0.23878872 | E11: 0 | F11: 0.051317614 | H11: 9 | I11: 45170 | J11: 1051 | K11: 1033 | L11: 0 | M11: 4326 | N11: 222
A12: 10 | B12: 45200 | C12: 0.38375315 | D12: 0.23060453 | E12: 0 | F12: 0.042191436 | H12: 10 | I12: 45200 | J12: 3047 | K12: 1831 | L12: 0 | M12: 7940 | N12: 335
A13: 11 | B13: 45231 | C13: 0.34666443 | D13: 0.22399597 | E13: 0 | F13: 0.034616031 | H13: 11 | I13: 45231 | J13: 2063 | K13: 1333 | L13: 0 | M13: 5951 | N13: 206
... A44: 42 | B44: 46174 | C44: 0.10444444 | D44: 0.18222222 | E44: 0.071111111 | F44: 0.0088888889 | H44: 42 | I44: 46174 | J44: 47 | K44: 82 | L44: 32 | M44: 450 | N44: 4
C46: =AVERAGE(C39:C43) -> 0.1405133 | D46: =AVERAGE(D39:D43) -> 0.15089036 | J46: =AVERAGE(J39:J43) -> 302.4 | K46: =AVERAGE(K39:K43) -> 316.6

Sheet рабоч
A1: какие сегменты по обороту имелись ввиду: хотим раскачать за счет S | B1: MPStsts за счет S, а M (2-3 тыс) и L (100) | E1: по этому отчету похоже на правду https://proteus.tcsbank.ru/superset/dashboard/46771/?native_filters_key=i_cpHlkPJC3wQAO8lt2_Tg8N-LHsXqmC68he0NAQEyNRwaKHgbBgPwIpTLJmR6wH
B2: Саша: SE до 100 млн годового оборота, ME 100млн-1млрд, LE >1млрд
B3: Карина: s до 120 млн в год, m до 16 млрд, по le нет верхнего порога
B4: преза от Н: S - 515 тыс, М - 31,5 , L - 1,8
B5: это типа малый средний и большой ибзнес?
A6: сегменты селлеров SE | B6: S - до 100 тыс, Core - 2 млн, M больше 2 млн
A8: кол- во селлеров Т - сегменты по оборотам | B8: https://proteus.tcsbank.ru/superset/dashboard/35207/?native_filters_key=6UD6_31FByJJBSkeo1OjteN2ZrhDe0UXwiQb27k-OI1_2btiTS-ROCrKRUs0NQiB | C8: Саша - уточняю по фильтрам
B9: t segment (апр 26) | C9: по чекам (апр 26)
A10: S | B10: 36400 | C10: 34500
A11: Core | B11: 36200 | C11: 28300
A12: M | B12: 4880 | C12: 4100
A13: Unk | B13: 1730 | C13: 12400
B14: =SUM(B10:B13) -> 79210 | C14: =SUM(C10:C13) -> 79300
A15: сколько остается за вычетом пересчений с МПС и Точкой? | B15: Карина?
A17: какому сегменту - какой тариф продавать? | B17: Карина в целом опредялеят?
B18: см текущие данные Селлер
A20: Отчет по базе селлеров
A21: https://proteus.tcsbank.ru/superset/dashboard/35207/?native_filters_key=aLN1Xx1yD5vdgsrx8uoA0pvrJEUqFxG78QxXMsGytEGq4tZDfgeCUsezc9HMrNwl
A23: t_segment | B23: по выплатам
A24: receipt_seller_segment | B24: по внешним чековым данным
A25: mnpl_segment | B25: маниплэйс, старый источник внешних данных по оборотам, данные получались парсингом, невалиден начиная с 2025-09-01
A30: в нашем отчете Селлер - по чековым данным
