Workbook

Sheet Гипотезы
A1: Гипотезы по вариантам - влиение на CR API и MAU Селлера
D2: Гипотеза | E2: Гипотеза | F2: Гипотеза
B3: AS IS (ранее когда для ОБ бесплатной требовался API) | C3: AS IS (апр-май) | D3: Вариант 1. Запрашивать только ключи MPStats | E3: Вариант 2. Запрашивать только ключи Т-Банка | F3: Вариант 3. Запрашивать ключи MPStats - для Т-Селлер, ключи Т-Банка для работы ОБ
D4: 1) тек кл - заново для Селлера, ОБ - как есть. 2) Нов кл - ОБ МПС не оч | E4: 1) тек кл - не будут заново ключ для Селлера(?), ОБ - как есть | F4: 1) тек кл - заново для Селлера, ОБ - как есть. 2) Тек и нов - оставлять ключ по 2 раза 3) (+)Нов кл - ОБ меньше прав
A5: База непротухших ключей | B5: ? | C5: 28600 | D5: - | E5: - | F5: -
A6: Пересечения по ключам | D6: - | E6: - | F6: -
A7: ключи: ОБ платная | B7: ? | C7: ='От Саши+Вопросы'!B11 -> 419 | D7: - | E7: - | F7: -
A8: ключи: ОБ платная + Селлер | B8: ? | C8: ='От Саши+Вопросы'!B10 -> 864 | D8: - | E8: - | F8: -
A9: ключи: Селлер ?? | B9: - | C9: ='От Саши+Вопросы'!B12 -> 26378 | D9: - | E9: - | F9: - | G9: Фактически это же просто остаток от пересечений?
A10: ключи: ОБ всего | B10: ? | G10: Нужно бы понять - сколько реально ключей были даны для ОБ и они не пойдут в Селлер (по историч данным дали АПИ, использовали ОБ, нно не заходили повторно в Селлер)
A11: Доля ключей - для ОБ всего | B11: ? | C11: ? | D11: - | E11: - | F11: -
A13: База активных API - не смогут использовать продукт без повторного оставления API
A14: текущие клиенты сервисов с ключами:
A15: Селлер | B15: - | C15: =C22 -> 9319 | D15: =C22 -> 9319 | E15: =D15-C7 -> 8900 | F15: =D15 -> 9319
A16: ОБ платная | B16: - | C16: =C7+C8 -> 1283 | D16: =C7+C8 -> 1283 | E16: 0 | F16: 0
A17: потенциальная реактиваци клиентов с ключами:
A18: Селлер | B18: =C5*(100%-100%-B11) -> #VALUE! | C18: =C5*(100%-100%-C11) -> #VALUE! | D18: =C5-C22 -> 19281 | E18: =C5-C22-(C7+C8) -> 17998 | F18: =D18 -> 19281 | G18: Текущий расчет в желтых ячейках кажется некорректный. Надо бы учесть долю ОБ реальную - срока 11
A20: Текущее использование сервиса + Реактивация
A21: текущие клиенты сервисов с ключами: | D21: прогноз | E21: прогноз | F21: прогноз
A22: Селлер MAU | C22: ='От Саши+Вопросы'!B4 -> 9319 | G22: как в итоге посчитать сколько отвалятся?из тек MAU отнять (гипотеза сколько не будут оставлять повтрно) из тех кто должен (строка 15) + как-то применить изменение CR API (строки 27-66)
A23: Селлер ACT 1+ | C23: ='От Саши+Вопросы'!B5 -> 4300
A24: Доля Act | C24: =C23/C22 -> 0.4614229
A25: Пронокновение | C25: =C23/C26 -> 0.05375
A26: Селлеров в Т | C26: 80000
A29: потенциальные клиенты с ключами - реактивация:
A30: Селлер MAU | G30: как в итоге посчитать сколько отвалятся?отнять (гипотеза сколько не будут оставлять повтрно) из тех кто должен - из базы (строка 18) + как-то применить изменение CR API (строки 27-66)
A31: Селлер ACT 1+
A32: ОБ MAU
A33: ОБ+Селлер MAU
A37: Первичное оставление API ключа | D37: Первич АПИ снижение (имя): Селлер - 5%, ОБ - 15% | E37: - | F37: Первич АПИ повышение (имя+права): Селлер - 5%, ОБ - 20%
F38: Првич АПИ снижение (два раза - для ОБ и Селлера): ? | G38: см конверию в повторн апи?/ иначе прикинуть?
A39: посещение страницы API | C39: в мес (янв-мар 26 ср)
A40: Селлер | C40: ? | D40: ? | E40: ? | F40: ?
A41: ОБ | C41: ? | D41: ? | E41: ? | F41: ? | G41: Новых клиентов ОБ в мес?
A42: ALL | C42: 1948 | D42: =C42 -> 1948 | E42: =C42 -> 1948 | F42: ?
A43: осталвение API
A44: Селлер | C44: ? | D44: ? | E44: ? | F44: ?
A45: ОБ | C45: ? | D45: ? | E45: ? | F45: ?
A46: ALL | C46: 725 | D46: =D50*C42 -> 688.75 | E46: =E50*E42 -> 725
A47: CR в оставление API
...

Sheet От Саши+Вопросы
A1: Метрики для расчета гипотез
A2: https://jira.tcsbank.ru/browse/ECA-2042 | B2: с начала апреля /на конец мая 26
A3: непротухших API ключей | B3: 28600 | C3: а сколько всего из них были пользователеми ОБ (не обязательно платной) и заходили в Селлер после оставления АПИ?
A4: MAU Селлер | B4: 9319 | C4: среди них есть одноразовые - для оставления API для ОБ?
A5: ACT 1+ Селлер | B5: 4300
A6: Отток Селлер | B6: =B3-B4 -> 19281 | C6: а бесплатная ОБ?
A10: пересечение клиентов платной ОБ(Бухгалтерия+, только с наличием признака селлера) и аудитории селлера активной по API | B10: 864
A11: только ОБ платаная | B11: 419
A12: только Селлер | B12: 26378 | C12: Ранее ОБ была бесплатной и требовался API? Какжется неорректно все оносить на Селлер
A15: Очень оценочная цифра по Бухгалтерии+ | B15: 2500 | C15: а что за метрика?
A18: CR в повторное оставление API | B18: 0.22 | C18: это СR из протухших ключей - в успешно оставленные ключи повторно?
C19: тут малые абсолюты 9платная ОБ)?
C20: Кажется нужно посомтреть на периоде ранее (когда ключи собирала не только для платного ОБ)?
