Workbook

Sheet PnL_upd 28 июл
G1: Комментарии
B2: Период расчета в модели: год | C2: Вариант 1 | E2: Вариант 2.1 | G2: NEW. В модели учтено получение комиссии Т - только от первых оплат МПСтатс + сокращены расходы Т на маркетинг
C3: Биллинг Т | E3: Биллинг МПС (с рекуррентами и ковенантами)
A4: Доходы: Тарифы MPStats оплачены клиентами | B4: Клиентский доход (тарифы МПСтатс) - от всей базы селлеров (~12 мес) | C4: =Воронка!R44 -> 1.4127074e+08 | E4: =C4 -> 1.4127074e+08
B5: Клиентский доход (тарифы МПСтатс) - 6 мес (неактуально) | C5: ='период вознаграждения'!G6 -> 1.3907468e+08 | E5: =C5 -> 1.3907468e+08
B6: Клиентский доход (тарифы МПСтатс) - 3 мес (неактуально) | C6: ='период вознаграждения'!M6 -> 73059219 | E6: =C6 -> 73059219
B7: Клиентский доход (тарифы МПСтатс) - первая оплата (на разн. кол-во мес) | C7: ='период вознаграждения'!T6 -> 84930192 | E7: =C7 -> 84930192 | G7: NEW. Upd - 27 июля - прогноз первых оплат - по ср чеку первой оплаты от МПС после обнолвения тарифов (в начале июня) - 84 930 192 руб - применила этот вариант, более точно
B9: Расходы Т-Банк
B10: Договор 1 (лицензия + техподдержка ПО МПСтатс)
B11: услуги по договору | C11: лицензия + техподдержка | E11: лицензия + техподдержка
A12: Договор 1 (лицензия и тех поддержка со стороны МПСтатс) | B12: Лицензия на ПО MPStats (ежегодно) | C12: 396000 | E12: =C12 -> 396000 | G12: NEW - Стоимость от МПСтатс - 396 000 руб. Отправить расчет лицензии налоговикам - спарвочно, чтобы была инофрмация по запросу. Оплата ежегоднго. Провалидировать с налогами и юристами - ОК.
A13: Лицензия на ПО MPStats -- какая минимально возможная? (единоразово бессрочно) | B13: Тех. поддержка ПО MPStats (в год) | C13: ='доп расходы_свод'!C17 -> 360000 | E13: =C13 -> 360000 | G13: по расчету МПС
A14: Тех. поддержка интеграции в целом от MPStats (в год) | B14: ИТОГО по Договору 1 | C14: =C12+C13 -> 756000 | E14: =E12+E13 -> 756000 | G14: Доход для МПС, расход для Т
B15: доля от клиентского дохода MPStats | C15: =C14/C$4 -> 0.0053514265 | E15: =E14/E$4 -> 0.0053514265
B16: Договор 2 (биллинг + лидген)
B17: услуги по договору | C17: биллинг + техподдержка + лидогенерация Т | E17: лидогенерация + техподдержка Т
A18: Расходы на привлечение Т-Банк | B18: 1. Расходы на привлечение Т-Банк | C18: =SUM(C19:C21) -> 4046442.6 | E18: =SUM(E19:E21) -> 4046442.6
A19: Расходы на внутренний маркетинг (запуск 6 кампаний) | B19: Расходы на внутренний маркетинг | C19: ='расходы для PnL'!B3/6*2 -> 1500000 | E19: ='расходы для PnL'!C3/6*2 -> 1500000 | G19: скоратили косты на маркетинг - запуск 2 кампаний
A20: Расходы на внешний маркетинг (медиа, тг) | B20: Расходы на внешний маркетинг | C20: ='расходы для PnL'!B4 -> 1500000 | E20: ='расходы для PnL'!C4 -> 1500000 | G20: медиа, ТГ
A21: Расходы на API запросы к маркетплейсам на время триал (бесплатная версия полного продуката MPStats на 14 дней) | B21: Расходы на API запросы к маркетплейсам на время триал | C21: ='расходы для PnL'!B5 -> 1046442.6 | E21: ='расходы для PnL'!C5 -> 1046442.6 | G21: Т несет расходы в период пользования клиентами продуката MPStats - триал на 14 дней (возможно затраты будут меньше, если кол-во дней триала меньше)
A22: Расходы на биллинг Т-Банк | B22: 2. Расходы на биллинг Т-Банк | C22: =SUM(C23:C25) -> 3072857.1 | E22: =SUM(E23:E25) -> 500000
A23: Разработка Биллинга от Т-Банк | B23: Разработка Биллинга от Т-Банк | C23: ='расходы для PnL'!B7 -> 1800000 | E23: ='расходы для PnL'!C7 -> 500000
A24: Бухгалтерское сопровождение биллинга | B24: Бухгалтерское сопровождение биллинга | C24: ='расходы для PnL'!B8 -> 0 | E24: ='расходы для PnL'!C8 -> 0 | G24: нет данных для расчета
B25: Техподдержка биллинг | C25: ='расходы для PnL'!B9 -> 1272857.1
A26: Тех. поддержка интеграции в целом от Т-Банк | B26: 3. Техподдержка Т-банк интеграции | C26: ='расходы для PnL'!B10 -> 1272857.1 | E26: ='расходы для PnL'!C10 -> 1272857.1
A27: Расходы на запросы к API Т-Банк (необходимо для базовой работы сервиса) | B27: 4. Расходы на запросы к API Т-Банк | C27: ='расходы для PnL'!B11 -> 7956567.1 | E27: ='расходы для PnL'!C11 -> 7956567.1 | G27: необходимо для базовой работы сервиса
B28: ИТОГО расходы Т | C28: =SUM(C18,C22,C26,C27) -> 16348724 | E28: =SUM(E18,E22,E26,E27) -> 13775867
B29: маржа Т поверх расходов | C29: 0.15 | E29: 0.16 | G29: 10% - мин.требование налогов Т для рыночности сделки
B31: Стоимость для договора 2 (калькуляция от затрат + маржа)
B32: Биллинг | C32: =C22*(1+C$29) -> 3533785.7 | E32: 0 | G32: разработка+интеграция +маржа Т
B33: доля от клиентского дохода MPStats (бессрочно) | C33: =C32/C$4 -> 0.025014279 | E33: =E32/E$4 -> 0
B34: Лидогенерация Т (вкл расходы техподдержка Т + API) | C34: =(C18+C26+C27)*(1+C$29) -> 15267247 | E34: =(E18+E26+E27+E22)*(1+E$29) -> 15980006 | G34: внешний/внутренний маркетинг Т + расходы на API/техподдержку +маржа 10%
B35: % от клиентского дохода (12 мес) - неактуально | C35: =C$34/C4 -> 0.10807083 | E35: =E$34/E4 -> 0.11311617
B36: % от клиентского дохода (6 мес) - неактуально | C36: =C$34/C5 -> 0.10977733 | E36: =E$34/E5 -> 0.11490234
B37: % от клиентского дохода (3 мес) - неактуально | C37: =C$34/C6 -> 0.20897085 | E37: =E$34/E6 -> 0.21872675
B38: % от клиентского дохода (первая оплата) | C38: =C$34/C7 -> 0.1797623 | E38: =E$34/E7 -> 0.18815459
B39: ИТОГО по Договору 2 (расчет 1: расходы Т+ маржа) | C39: =C32+C34 -> 18801033 | E39: =E32+E34 -> 15980006 | G39: Доход для Т, расход для МПС
B40: % от клиентского дохода (12 мес) | C40: =C39/C4 -> 0.13308511 | E40: =E39/E4 -> 0.11311617
B42: Стоимость для договора 2 (калькуляция от клиентских доходов)
B43: Биллинг Т | C43: =C$4*C47 -> 3533785.7 | E43: =E$4*E47 -> 0
...

Sheet ИТОГ_new v4_первые оплаты
G1: Комментарии
B2: Период расчета в модели: год | C2: Вариант 1 | E2: Вариант 2.1 | G2: NEW. В модели учтено получение комиссии Т - от первых оплат МПСтатс
C3: Биллинг Т | E3: Биллинг МПС (с рекуррентами и ковенантами)
A4: Доходы: Тарифы MPStats оплачены клиентами | B4: Клиентский доход (тарифы МПСтатс) - от всей базы селлеров (~12 мес) | C4: =Воронка!#REF! -> #REF! | E4: =Воронка!#REF! -> #REF!
B5: Клиентский доход (тарифы МПСтатс) - 6 мес | C5: ='период вознаграждения'!G6 -> 1.3907468e+08 | E5: =C5 -> 1.3907468e+08
B6: Клиентский доход (тарифы МПСтатс) - 3 мес | C6: ='период вознаграждения'!M6 -> 73059219 | E6: =C6 -> 73059219
B7: Клиентский доход (тарифы МПСтатс) - первая оплата (на разн. кол-во мес) | C7: ='период вознаграждения'!T6 -> 84930192 | E7: =C7 -> 84930192 | G7: NEW. Прикинула 2 варианта 1) Инфо по кол-ву мес по первым оплатам по новым тарифам (с началак июня) - от МПС. Сумму первых оплат считала по LTV от МПС более ранним данным - 78 682 122 руб 2) Upd - 27 июля - по ср чеку первой оплаты от МПС после обнолвения тарифов (в начале июня) - 84 930 192 руб - применила этот вариант, более точно
B9: Расходы Т-Банк
B10: Договор 1 (лицензия + техподдержка ПО МПСтатс)
B11: услуги по договору | C11: лицензия + техподдержка | E11: лицензия + техподдержка
A12: Договор 1 (лицензия и тех поддержка со стороны МПСтатс) | B12: Лицензия на ПО MPStats (ежегодно) | C12: 396000 | E12: =C12 -> 396000 | G12: NEW - Стоимость от МПСтатс - 396 000 руб. Отправить расчет лицензии налоговикам - спарвочно, чтобы была инофрмация по запросу. Оплата ежегоднго. Провалидировать с налогами и юристами - ОК.
A13: Лицензия на ПО MPStats -- какая минимально возможная? (единоразово бессрочно) | B13: Тех. поддержка ПО MPStats (в год) | C13: ='доп расходы_свод'!C17 -> 360000 | E13: =C13 -> 360000 | G13: по расчету МПС
A14: Тех. поддержка интеграции в целом от MPStats (в год) | B14: ИТОГО по Договору 1 | C14: =C12+C13 -> 756000 | E14: =E12+E13 -> 756000 | G14: Доход для МПС, расход для Т
B15: доля от клиентского дохода MPStats | C15: =C14/C$4 -> #REF! | E15: =E14/E$4 -> #REF!
B16: Договор 2 (биллинг + лидген)
B17: услуги по договору | C17: биллинг + техподдержка + лидогенерация Т | E17: лидогенерация + техподдержка Т
A18: Расходы на привлечение Т-Банк | B18: 1. Расходы на привлечение Т-Банк | C18: =SUM(C19:C21) -> #REF! | E18: =SUM(E19:E21) -> #REF!
A19: Расходы на внутренний маркетинг (запуск 6 кампаний) | B19: Расходы на внутренний маркетинг | C19: =Воронка!#REF! -> #REF! | E19: =Воронка!#REF! -> #REF! | G19: запуск 6 кампаний (исх). можно сократить косты на маркетинг
A20: Расходы на внешний маркетинг (медиа, тг) | B20: Расходы на внешний маркетинг | C20: =Воронка!#REF! -> #REF! | E20: =Воронка!#REF! -> #REF! | G20: медиа, ТГ
A21: Расходы на API запросы к маркетплейсам на время триал (бесплатная версия полного продуката MPStats на 14 дней) | B21: Расходы на API запросы к маркетплейсам на время триал | C21: =Воронка!#REF! -> #REF! | E21: =Воронка!#REF! -> #REF! | G21: Т несет расходы в период пользования клиентами продуката MPStats - триал на 14 дней. Возможно затраты будут меньше, если кол-во дней триала меньше
A22: Расходы на биллинг Т-Банк | B22: 2. Расходы на биллинг Т-Банк | C22: =SUM(C23:C25) -> #REF! | E22: =SUM(E23:E25) -> #REF!
A23: Разработка Биллинга от Т-Банк | B23: Разработка Биллинга от Т-Банк | C23: =Воронка!#REF! -> #REF! | E23: =Воронка!#REF! -> #REF!
A24: Бухгалтерское сопровождение биллинга | B24: Бухгалтерское сопровождение биллинга | C24: =Воронка!#REF! -> #REF! | E24: =Воронка!#REF! -> #REF! | G24: нет данных для расчета
B25: Техподдержка биллинг | C25: =расходы_разработка!D50-расходы_разработка!E50 -> 1272857.1
A26: Тех. поддержка интеграции в целом от Т-Банк | B26: 3. Техподдержка Т-банк интеграции | C26: =расходы_разработка!D50-расходы_разработка!E50 -> 1272857.1 | E26: =расходы_разработка!E50 -> 1272857.1
A27: Расходы на запросы к API Т-Банк (необходимо для базовой работы сервиса) | B27: 4. Расходы на запросы к API Т-Банк | C27: =Воронка!#REF! -> #REF! | E27: =Воронка!#REF! -> #REF! | G27: необходимо для базовой работы сервиса
B28: ИТОГО расходы Т | C28: =SUM(C18,C22,C26,C27) -> #REF! | E28: =SUM(E18,E22,E26,E27) -> #REF!
B29: маржа поверх расходов | C29: 0.14 | E29: 0.15 | G29: 10% - мин.требование налогов Т для рыночности сделки
B31: Стоимость для договора 2 (калькуляция от затрат + маржа)
B32: Биллинг | C32: =C22*(1+C$29) -> #REF! | E32: 0 | G32: разработка+интеграция +маржа Т
B33: доля от клиентского дохода MPStats (бессрочно) | C33: =C32/C$4 -> #REF! | E33: =E32/E$4 -> #REF!
B34: Лидогенерация Т (вкл расходы техподдержка Т + API) | C34: =(C18+C26+C27)*(1+C$29) -> #REF! | E34: =(E18+E26+E27+E22)*(1+E$29) -> #REF! | G34: внешний/внутренний маркетинг Т + расходы на API/техподдержку +маржа 10%
B35: % от клиентского дохода (12 мес) | C35: =C$34/C4 -> #REF! | E35: =E$34/E4 -> #REF!
B36: % от клиентского дохода (6 мес) | C36: =C$34/C5 -> #REF! | E36: =E$34/E5 -> #REF!
B37: % от клиентского дохода (3 мес) | C37: =C$34/C6 -> #REF! | E37: =E$34/E6 -> #REF!
B38: % от клиентского дохода (первая оплата) | C38: =C$34/C7 -> #REF! | E38: =E$34/E7 -> #REF!
B39: ИТОГО по Договору 2 (расчет 1: расходы Т+ маржа) | C39: =C32+C34 -> #REF! | E39: =E32+E34 -> #REF! | G39: Доход для Т, расход для МПС
B40: % от клиентского дохода (12 мес) | C40: =C39/C4 -> #REF! | E40: =E39/E4 -> #REF!
B42: Стоимость для договора 2 (калькуляция от клиентских доходов)
B43: Биллинг Т | C43: =C$4*C47 -> #REF! | E43: =E$4*E47 -> #REF!
...

Sheet первые оплаты
A1: Категория доходов | B1: Срок | C1: Кол-во пользователей | D1: Вклад | F1: Категория доходов | G1: Кол-во пользователей | H1: Вклад | I1: Средний срок (мес.)
A2: 1_неизвестно | B2: 0 | C2: 1 | D2: =B2*C2 -> 0 | F2: 1_неизвестно | G2: =SUM(C2:C7) -> 191 | H2: =SUM(D2:D7) -> 408 | I2: =H2/G2 -> 2.1361257
A3: 1_неизвестно | B3: 1 | C3: 140 | D3: =B3*C3 -> 140 | F3: 2_<1 млн | G3: =SUM(C8:C12) -> 161 | H3: =SUM(D8:D12) -> 507 | I3: =H3/G3 -> 3.1490683
A4: 1_неизвестно | B4: 2 | C4: 2 | D4: =B4*C4 -> 4 | F4: 3_1-10 млн | G4: =SUM(C13:C17) -> 102 | H4: =SUM(D13:D17) -> 374 | I4: =H4/G4 -> 3.6666667
A5: 1_неизвестно | B5: 3 | C5: 28 | D5: =B5*C5 -> 84 | F5: 4_10+млн | G5: =SUM(C18:C21) -> 37 | H5: =SUM(D18:D21) -> 166 | I5: =H5/G5 -> 4.4864865
A6: 1_неизвестно | B6: 6 | C6: 10 | D6: =B6*C6 -> 60
A7: 1_неизвестно | B7: 12 | C7: 10 | D7: =B7*C7 -> 120
A8: 2_<1 млн | B8: 1 | C8: 94 | D8: =B8*C8 -> 94
A9: 2_<1 млн | B9: 2 | C9: 1 | D9: =B9*C9 -> 2
A10: 2_<1 млн | B10: 3 | C10: 35 | D10: =B10*C10 -> 105
A11: 2_<1 млн | B11: 6 | C11: 11 | D11: =B11*C11 -> 66
A12: 2_<1 млн | B12: 12 | C12: 20 | D12: =B12*C12 -> 240
A13: 3_1-10 млн | B13: 0 | C13: 2 | D13: =B13*C13 -> 0
A14: 3_1-10 млн | B14: 1 | C14: 53 | D14: =B14*C14 -> 53
A15: 3_1-10 млн | B15: 3 | C15: 21 | D15: =B15*C15 -> 63
A16: 3_1-10 млн | B16: 6 | C16: 9 | D16: =B16*C16 -> 54
A17: 3_1-10 млн | B17: 12 | C17: 17 | D17: =B17*C17 -> 204
... A21: 4_10+млн | B21: 12 | C21: 9 | D21: =B21*C21 -> 108
B26: Кол-во пользователей | C26: Сумма оплаты
A27: 1_неизвестно | B27: 191 | C27: 3752242
A28: 0 | B28: 1 | C28: 666
A29: 1 | B29: 140 | C29: 1583647
A30: 2 | B30: 2 | C30: 10000
A31: 3 | B31: 28 | C31: 783108
A32: 6 | B32: 10 | C32: 594903
A33: 12 | B33: 10 | C33: 779918
A34: 2_<1 млн | B34: 161 | C34: 4477202
A35: 1 | B35: 94 | C35: 1024717
A36: 2 | B36: 1 | C36: 25980
A37: 3 | B37: 35 | C37: 874673
A38: 6 | B38: 11 | C38: 506114
A39: 12 | B39: 20 | C39: 2045718
A40: 3_1-10 млн | B40: 102 | C40: 3392809
A41: 0 | B41: 2 | C41: 5500
A42: 1 | B42: 53 | C42: 616841
A43: 3 | B43: 21 | C43: 721044
A44: 6 | B44: 9 | C44: 418312
A45: 12 | B45: 17 | C45: 1631112
A46: 4_10+млн | B46: 37 | C46: 2024535
A47: 1 | B47: 19 | C47: 383254
...

Sheet Воронка
F1: 1.1 Биллинг MPS as is (нет реккурентов и ковенант) | M1: 2. Биллинг Т-Банк | S1: Биллинг Т-Банк | AB1: Биллинг Т-Банк
F2: Гипотеза 1. Биллинг MPS + Sales (as is - без реккурентнтов и ковенант) | M2: Гипотеза 2.Биллинг Т / Биллинг MPS (с рекуррентами и ковенанатами)+ Sales Mpstast | S2: Гипотеза 3.Digital + Биллинг Т -- перепроверить формулы в этом варианте (вреотяно местами некорректные) | AB2: Гипотеза 4. Digital + Sales MPS (> 1млн) + Биллинг Т ---- перепроверить формулы в этом варианте (вреотяно местами некорректные)
AB3: Digital (до 1 млн оборот) | AH3: Sales (>1 млн оборот)
A4: Воронка | B4: Конверсии как дали MPStats | C4: Конверсии как дали MPStats | D4: От какого этапа | E4: От всех лидов | F4: Конверсии | G4: Сегмент 1. Активные клиенты в Т с выплатами от МП. 1 приоритет | H4: Сегмент 2. Активные клиенты в Т., но без выплат от МП на РКО. | I4: Сегмент 3. Спящие клиенты в Т (нет транзакций по РКО). Проснулись | J4: Сегмент 4. Клиенты без РКО в Т - Рынок. Открыли РКО | K4: ALL | L4: От всех лидов | M4: Конверсии | N4: Сегмент 1. Активные селлеры в Т с выплатами от МП. 1 приоритет | O4: Сегмент 2. Активные селлеры в Т., но без выплат от МП | P4: Сегмент 3. Спящие селлеры в Т (нет транзакций по РКО) | Q4: Сегмент 4. Селлеры без РКО в Т - Рынок | R4: ALL | S4: Конверсии | T4: Сегмент 1. Активные селлеры в Т с выплатами от МП. 1 приоритет | U4: Сегмент 2. Активные селлеры в Т., но без выплат от МП | V4: Сегмент 3. Спящие селлеры в Т (нет транзакций по РКО) | W4: Сегмент 4. Селлеры без РКО в Т - Рынок | X4: ALL | Y4: От все Лиды Digital | Z4: От все Лиды Sales | AA4: От все Лиды | AB4: Конверсии | AC4: Сегмент 1. Активные селлеры в Т с выплатами от МП. 1 приоритет | AD4: Сегмент 2. Активные селлеры в Т., но без выплат от МП | AE4: Сегмент 3. Спящие селлеры в Т (нет транзакций по РКО) | AF4: Сегмент 4. Селлеры без РКО в Т - Рынок | AG4: ALL Digital | AH4: Конверсии | AI4: Сегмент 1. Активные селлеры в Т с выплатами от МП. 1 приоритет | AJ4: Сегмент 2. Активные селлеры в Т., но без выплат от МП | AK4: Сегмент 3. Спящие селлеры в Т (нет транзакций по РКО) | AL4: Сегмент 4. Селлеры без РКО в Т - Рынок | AM4: ALL Sales | AN4: ALL
A5: База селлеров | F5: 1 | G5: ='База селлеров'!B63 -> 79000 | H5: ='База селлеров'!C63 -> 33000 | I5: ='База селлеров'!D67 -> 1820 | J5: ='База селлеров'!E67 -> 3705 | K5: =SUM(G5:J5) -> 117525 | M5: =F5 -> 1 | N5: =G5 -> 79000 | O5: =H5 -> 33000 | P5: =I5 -> 1820 | Q5: =J5 -> 3705 | R5: =SUM(N5:Q5) -> 117525 | S5: =M5 -> 1 | T5: =N5 -> 79000 | U5: =O5 -> 33000 | V5: =P5 -> 1820 | W5: =Q5 -> 3705 | X5: =SUM(T5:W5) -> 117525 | AC5: =T5*T91 -> 70079.175 | AD5: =U5*U91 -> 27249.295 | AE5: =V5*V91 -> 1564.9858 | AF5: =W5*W91 -> 3185.8639 | AG5: =SUM(AC5:AF5) -> 102079.32 | AI5: =T5-AC5 -> 8920.8253 | AJ5: =U5-AD5 -> 5750.7049 | AK5: =V5-AE5 -> 255.01424 | AL5: =W5-AF5 -> 519.13612 | AM5: =SUM(AI5:AL5) -> 15445.681 | AN5: =AG5+AM5 -> 117525
A6: Увеличение базы - влияние MPStast | I6: ='База селлеров'!D69 -> 130 | J6: ='База селлеров'!E69 -> 1233 | P6: =I6 -> 130 | Q6: =J6 -> 1233 | V6: =P6 -> 130 | W6: =Q6 -> 1233 | AE6: =V6*V91 -> 111.7847 | AF6: =W6*W91 -> 1060.2349 | AK6: =V6-AE6 -> 18.215303 | AL6: =W6-AF6 -> 172.76514
A7: Лиды (визиты Селлер) | C7: 1 | D7: от Базы | F7: 0.5 | G7: =G5*$F$7 -> 39500 | H7: =H5*$F$7 -> 16500 | I7: =I5*$F$7 -> 910 | J7: =J5*$F$7 -> 1852.5 | K7: =SUM(G7:J7) -> 58762.5 | M7: =F7 -> 0.5 | N7: =G7 -> 39500 | O7: =H7 -> 16500 | P7: =I7 -> 910 | Q7: =J7 -> 1852.5 | R7: =SUM(N7:Q7) -> 58762.5 | S7: =M7 -> 0.5 | T7: =N7 -> 39500 | U7: =O7 -> 16500 | V7: =P7 -> 910 | W7: =Q7 -> 1852.5 | X7: =SUM(T7:W7) -> 58762.5 | AB7: =S7 -> 0.5 | AC7: =$AB$7*AC5 -> 35039.587 | AD7: =$AB$7*AD5 -> 13624.648 | AE7: =$AB$7*AE5 -> 782.49288 | AF7: =$AB$7*AF5 -> 1592.9319 | AG7: =SUM(AC7:AF7) -> 51039.66 | AH7: =M7 -> 0.5 | AI7: =$AH$7*AI5 -> 4460.4126 | AJ7: =$AH$7*AJ5 -> 2875.3524 | AK7: =$AH$7*AK5 -> 127.50712 | AL7: =$AH$7*AL5 -> 259.56806 | AM7: =SUM(AI7:AL7) -> 7722.8403 | AN7: =AG7+AM7 -> 58762.5
A8: Оставление API ключа | F8: 0.35 | G8: =$F8*G7 -> 13825 | H8: =$F8*H7 -> 5775 | I8: =$F8*I7 -> 318.5 | J8: =$F8*J7 -> 648.375 | K8: =SUM(G8:J8) -> 20566.875 | M8: 0.35 | N8: =$F8*N7 -> 13825 | O8: =$F8*O7 -> 5775 | P8: =$F8*P7 -> 318.5 | Q8: =$F8*Q7 -> 648.375 | R8: =SUM(N8:Q8) -> 20566.875 | S8: 0.35 | T8: =$F8*T7 -> 13825 | U8: =$F8*U7 -> 5775 | V8: =$F8*V7 -> 318.5 | W8: =$F8*W7 -> 648.375 | X8: =SUM(T8:W8) -> 20566.875 | AB8: 0.35 | AC8: =$F8*AC7 -> 12263.856 | AD8: =$F8*AD7 -> 4768.6266 | AE8: =$F8*AE7 -> 273.87251 | AF8: =$F8*AF7 -> 557.52618 | AG8: =SUM(AC8:AF8) -> 17863.881 | AH8: 0.35 | AI8: =$F8*AI7 -> 1561.1444 | AJ8: =$F8*AJ7 -> 1006.3734 | AK8: =$F8*AK7 -> 44.627491 | AL8: =$F8*AL7 -> 90.848822 | AM8: =SUM(AI8:AL8) -> 2702.9941 | AN8: =AG8+AM8 -> 20566.875
A9: Оффер триала
A10: Триала выдан
A11: Активация триала | F11: 0.21 | G11: =$F11*G7 -> 8295 | H11: =$F11*H7 -> 3465 | I11: =$F11*I7 -> 191.1 | J11: =$F11*J7 -> 389.025 | K11: =SUM(G11:J11) -> 12340.125 | M11: 0.21 | N11: =$F11*N7 -> 8295 | O11: =$F11*O7 -> 3465 | P11: =$F11*P7 -> 191.1 | Q11: =$F11*Q7 -> 389.025 | R11: =SUM(N11:Q11) -> 12340.125 | S11: 0.21 | T11: =$F11*T7 -> 8295 | U11: =$F11*U7 -> 3465 | V11: =$F11*V7 -> 191.1 | W11: =$F11*W7 -> 389.025 | X11: =SUM(T11:W11) -> 12340.125 | AB11: 0.21 | AC11: =$F11*AC7 -> 7358.3133 | AD11: =$F11*AD7 -> 2861.176 | AE11: =$F11*AE7 -> 164.32351 | AF11: =$F11*AF7 -> 334.51571 | AG11: =SUM(AC11:AF11) -> 10718.329 | AH11: 0.21 | AI11: =$F11*AI7 -> 936.68665 | AJ11: =$F11*AJ7 -> 603.82401 | AK11: =$F11*AK7 -> 26.776495 | AL11: =$F11*AL7 -> 54.509293 | AM11: =SUM(AI11:AL11) -> 1621.7965 | AN11: =AG11+AM11 -> 12340.125
A12: Активация в Селлере
A13: Квалификацированные лиды ЦА (не дозвон КЦ) | D13: от Лиды | F13: =G13/G7 -> 0.25 | G13: =G7-G14 -> 9875 | H13: =H7-H14 -> 4125 | I13: =I7-I14 -> 227.5 | J13: =J7-J14 -> 463.125 | K13: =SUM(G13:J13) -> 14690.625 | M13: =N13/N7 -> 0.25 | N13: =N7-N14 -> 9875 | O13: =O7-O14 -> 4125 | P13: =P7-P14 -> 227.5 | Q13: =Q7-Q14 -> 463.125 | R13: =SUM(N13:Q13) -> 14690.625 | S13: - | T13: - | U13: - | V13: - | W13: - | X13: - | AH13: =M13 -> 0.25 | AI13: =AI7-AI14 -> 1115.1032 | AJ13: =AJ7-AJ14 -> 718.83811 | AK13: =AK7-AK14 -> 31.87678 | AL13: =AL7-AL14 -> 64.892016 | AM13: =SUM(AI13:AL13) -> 1930.7101 | AN13: =AG13+AM13 -> 1930.7101
A14: Квалификацированные лиды ЦА (дозвоны) | B14: от Лиды | C14: 0.13 | D14: от Лиды | F14: 0.75 | G14: =$G$7*F14 -> 29625 | H14: =$H$7*F14 -> 12375 | I14: =$I$7*F14 -> 682.5 | J14: =$J$7*F14 -> 1389.375 | K14: =SUM(G14:J14) -> 44071.875 | M14: =F14 -> 0.75 | N14: =$N$7*M14 -> 29625 | O14: =$O$7*M14 -> 12375 | P14: =$P$7*M14 -> 682.5 | Q14: =$Q$7*M14 -> 1389.375 | R14: =SUM(N14:Q14) -> 44071.875 | S14: - | T14: - | U14: - | V14: - | W14: - | X14: - | AH14: =M14 -> 0.75 | AI14: =$AI$7*AH14 -> 3345.3095 | AJ14: =$AJ$7*AH14 -> 2156.5143 | AK14: =$AK$7*AH14 -> 95.630339 | AL14: =$AL$7*AH14 -> 194.67605 | AM14: =SUM(AI14:AL14) -> 5792.1302 | AN14: =AG14+AM14 -> 5792.1302
A15: /Оффер демо встречи | B15: от Квалиф. Лиды | C15: 1 | D15: от Квал. Лиды | F15: 1 | G15: =$G$14*F15 -> 29625 | H15: =$H$14*F15 -> 12375 | I15: =$I$14*F15 -> 682.5 | J15: =$J$14*F15 -> 1389.375 | K15: =SUM(G15:J15) -> 44071.875 | M15: =F15 -> 1 | N15: =$N$7*M15 -> 39500 | O15: =$O$7*M15 -> 16500 | P15: =$P$7*M15 -> 910 | Q15: =$Q$7*M15 -> 1852.5 | R15: =SUM(N15:Q15) -> 58762.5 | S15: - | T15: - | U15: - | V15: - | W15: - | X15: - | AH15: =M15 -> 1 | AI15: =$AI$7*AH15 -> 4460.4126 | AJ15: =$AJ$7*AH15 -> 2875.3524 | AK15: =$AK$7*AH15 -> 127.50712 | AL15: =$AL$7*AH15 -> 259.56806 | AM15: =SUM(AI15:AL15) -> 7722.8403 | AN15: =AG15+AM15 -> 7722.8403
A16: //Согласились на демо встречу | B16: от Квалиф. Лиды | C16: 0.4 | D16: от Квал. Лиды | F16: ='Воронка MPS_обработано'!N10 -> 0.4 | G16: =$G$14*F16 -> 11850 | H16: =$H$14*F16 -> 4950 | I16: =$I$14*F16 -> 273 | J16: =$J$14*F16 -> 555.75 | K16: =SUM(G16:J16) -> 17628.75 | M16: =F16 -> 0.4 | N16: =$N$7*M16 -> 15800 | O16: =$O$7*M16 -> 6600 | P16: =$P$7*M16 -> 364 | Q16: =$Q$7*M16 -> 741 | R16: =SUM(N16:Q16) -> 23505 | S16: - | T16: - | U16: - | V16: - | W16: - | X16: - | AH16: =M16 -> 0.4 | AI16: =$AI$7*AH16 -> 1784.1651 | AJ16: =$AJ$7*AH16 -> 1150.141 | AK16: =$AK$7*AH16 -> 51.002847 | AL16: =$AL$7*AH16 -> 103.82722 | AM16: =SUM(AI16:AL16) -> 3089.1361 | AN16: =AG16+AM16 -> 3089.1361
A17: //Демо встреча состоялась | B17: от Квалиф. Лиды | C17: 0.298 | D17: от Квал. Лиды | F17: ='Воронка MPS_обработано'!N11 -> 0.298 | G17: =$G$14*F17 -> 8828.25 | H17: =$H$14*F17 -> 3687.75 | I17: =$I$14*F17 -> 203.385 | J17: =$J$14*F17 -> 414.03375 | K17: =SUM(G17:J17) -> 13133.419 | M17: =F17 -> 0.298 | N17: =$N$7*M17 -> 11771 | O17: =$O$7*M17 -> 4917 | P17: =$P$7*M17 -> 271.18 | Q17: =$Q$7*M17 -> 552.045 | R17: =SUM(N17:Q17) -> 17511.225 | S17: - | T17: - | U17: - | V17: - | W17: - | X17: - | AH17: =M17 -> 0.298 | AI17: =$AI$7*AH17 -> 1329.203 | AJ17: =$AJ$7*AH17 -> 856.85503 | AK17: =$AK$7*AH17 -> 37.997121 | AL17: =$AL$7*AH17 -> 77.351283 | AM17: =SUM(AI17:AL17) -> 2301.4064 | AN17: =AG17+AM17 -> 2301.4064
A18: /Дозвон sales (кто не согласился на демо) | B18: от Квалиф. Лиды | C18: 0.455 | D18: от Квал. Лиды | F18: ='Воронка MPS_обработано'!N12 -> 0.455 | G18: =$G$14*F18 -> 13479.375 | H18: =$H$14*F18 -> 5630.625 | I18: =$I$14*F18 -> 310.5375 | J18: =$J$14*F18 -> 632.16562 | K18: =SUM(G18:J18) -> 20052.703 | M18: =F18 -> 0.455 | N18: =$N$7*M18 -> 17972.5 | O18: =$O$7*M18 -> 7507.5 | P18: =$P$7*M18 -> 414.05 | Q18: =$Q$7*M18 -> 842.8875 | R18: =SUM(N18:Q18) -> 26736.938 | S18: - | T18: - | U18: - | V18: - | W18: - | X18: - | AH18: =M18 -> 0.455 | AI18: =$AI$7*AH18 -> 2029.4878 | AJ18: =$AJ$7*AH18 -> 1308.2854 | AK18: =$AK$7*AH18 -> 58.015739 | AL18: =$AL$7*AH18 -> 118.10347 | AM18: =SUM(AI18:AL18) -> 3513.8923 | AN18: =AG18+AM18 -> 3513.8923
A19: Покупка тарифа MPS (основной канал) | B19: от Лиды | C19: 0,7% / 0,41%/ 1,1% всего | D19: от Квал. Лиды | E19: =K19/K7 -> 0.064038462 | F19: ='Воронка MPS_обработано'!N14 -> 0.085384615 | G19: =$G$14*F19 -> 2529.5192 | H19: =$H$14*F19 -> 1056.6346 | I19: =$I$14*F19 -> 58.275 | J19: =$J$14*F19 -> 118.63125 | K19: =SUM(G19:J19) -> 3763.0601 | L19: =R19/R7 -> 0.096057692 | M19: =F19*1.5 -> 0.12807692 | N19: =N14*$M$19 -> 3794.2788 | O19: =O14*$M$19 -> 1584.9519 | P19: =P14*$M$19 -> 87.4125 | Q19: =Q14*$M$19 -> 177.94688 | R19: =SUM(N19:Q19) -> 5644.5901 | S19: ='Воронка Селлер as is'!F12 -> 0.017475399 | T19: =$S$19*T7 -> 690.27825 | U19: =$S$19*U7 -> 288.34408 | V19: =$S$19*V7 -> 15.902613 | W19: =$S$19*W7 -> 32.373176 | X19: =SUM(T19:W19) -> 1026.8981 | Y19: =AG19/$AG$7 -> 0.017475399 | Z19: =AM19/$AM$7 -> 0.096057692 | AA19: =AN19/AN7 -> 0.027803048 | AB19: =S19 -> 0.017475399 | AC19: =$S$19*AC7 -> 612.33076 | AD19: =$S$19*AD7 -> 238.09615 | AE19: =$S$19*AE7 -> 13.674375 | AF19: =$S$19*AF7 -> 27.837121 | AG19: =SUM(AC19:AF19) -> 891.9384 | AH19: =M19 -> 0.12807692 | AI19: =AI14*$AH$19 -> 428.45694 | AJ19: =AJ14*$AH$19 -> 276.19972 | AK19: =AK14*$AH$19 -> 12.24804 | AL19: =AL14*$AH$19 -> 24.933509 | AM19: =SUM(AI19:AL19) -> 741.83821 | AN19: =AG19+AM19 -> 1633.7766
A20: Покупка тарифа MPS (самоходы) | D20: от Лиды | E20: =K20/K7 -> 0.0043688497 | F20: =S19 -> 0.017475399 | G20: =G13*$F$20 -> 172.56956 | H20: =H13*$F$20 -> 72.08602 | I20: =I13*$F$20 -> 3.9756532 | J20: =J13*$F$20 -> 8.093294 | K20: =SUM(G20:J20) -> 256.72453 | L20: =R20/R7 -> 0.0043688497 | M20: =S19 -> 0.017475399 | N20: =N13*$M$20 -> 172.56956 | O20: =O13*$M$20 -> 72.08602 | P20: =P13*$M$20 -> 3.9756532 | Q20: =Q13*$M$20 -> 8.093294 | R20: =SUM(N20:Q20) -> 256.72453 | Y20: =AG20/$AG$7 -> 0 | Z20: =AM20/$AM$7 -> 0.0043688497 | AA20: =AN20/AN7 -> 0.00057417449 | AH20: =M20 -> 0.017475399 | AI20: =AI13*$AH$20 -> 19.486872 | AJ20: =AJ13*$AH$20 -> 12.561983 | AK20: =AK13*$AH$20 -> 0.55705943 | AL20: =AL13*$AH$20 -> 1.1340138 | AM20: =SUM(AI20:AL20) -> 33.739928 | AN20: =AG20+AM20 -> 33.739928
A21: Покупка тарифа MPS (всего) | E21: =K21/K7 -> 0.068407311 | G21: =SUM(G19:G20) -> 2702.0888 | H21: =SUM(H19:H20) -> 1128.7206 | I21: =SUM(I19:I20) -> 62.250653 | J21: =SUM(J19:J20) -> 126.72454 | K21: =SUM(G21:J21) -> 4019.7846 | L21: =R21/R7 -> 0.10042654 | N21: =SUM(N19:N20) -> 3966.8484 | O21: =SUM(O19:O20) -> 1657.0379 | P21: =SUM(P19:P20) -> 91.388153 | Q21: =SUM(Q19:Q20) -> 186.04017 | R21: =SUM(N21:Q21) -> 5901.3147 | T21: =T19 -> 690.27825 | U21: =U19 -> 288.34408 | V21: =V19 -> 15.902613 | W21: =W19 -> 32.373176 | X21: =SUM(T21:W21) -> 1026.8981 | Y21: =AG21/$AG$7 -> 0.017475399 | Z21: =AM21/$AM$7 -> 0.10042654 | AA21: =AN21/AN7 -> 0.028377223 | AC21: =AC19 -> 612.33076 | AD21: =AD19 -> 238.09615 | AE21: =AE19 -> 13.674375 | AF21: =AF19 -> 27.837121 | AG21: =SUM(AC21:AF21) -> 891.9384 | AI21: =SUM(AI19:AI20) -> 447.94382 | AJ21: =SUM(AJ19:AJ20) -> 288.7617 | AK21: =SUM(AK19:AK20) -> 12.805099 | AL21: =SUM(AL19:AL20) -> 26.067523 | AM21: =SUM(AI21:AL21) -> 775.57814 | AN21: =AG21+AM21 -> 1667.5165
A22: >100 млн | G22: =G$21*G88 -> 0.29496946 | H22: =H$21*H88 -> 1.9448507 | I22: =I$21*I88 -> 0.051336957 | J22: =J$21*J88 -> 0.10450738 | K22: =SUM(G22:J22) -> 2.3956645 | N22: =N$21*N88 -> 0.43303504 | O22: =O$21*O88 -> 2.8551719 | P22: =P$21*P88 -> 0.075366111 | Q22: =Q$21*Q88 -> 0.15342387 | R22: =SUM(N22:Q22) -> 3.5169969 | T22: =T$21*T88 -> 0.075353187 | U22: =U$21*U88 -> 0.49683347 | V22: =V$21*V88 -> 0.013114589 | W22: =W$21*W88 -> 0.026697557 | X22: =SUM(T22:W22) -> 0.6119988 | AC22: =AC$21*AC88 -> 0 | AD22: =AD$21*AD88 -> 0 | AE22: =AE$21*AE88 -> 0 | AF22: =AF$21*AF88 -> 0 | AG22: =SUM(AC22:AF22) -> 0 | AI22: =AI$21*AI88 -> 0.43303504 | AJ22: =AJ$21*AJ88 -> 2.8551719 | AK22: =AK$21*AK88 -> 0.075366111 | AL22: =AL$21*AL88 -> 0.15342387 | AM22: =SUM(AI22:AL22) -> 3.5169969 | AN22: =AG22+AM22 -> 3.5169969
A23: 10-100 млн | G23: =G$21*G89 -> 20.268616 | H23: =H$21*H89 -> 23.161404 | I23: =I$21*I89 -> 0.82625481 | J23: =J$21*J89 -> 1.6820187 | K23: =SUM(G23:J23) -> 45.938293 | N23: =N$21*N89 -> 29.755693 | O23: =O$21*O89 -> 34.002502 | P23: =P$21*P89 -> 1.2129977 | Q23: =Q$21*Q89 -> 2.4693168 | R23: =SUM(N23:Q23) -> 67.44051 | T23: =T$21*T89 -> 5.1778404 | U23: =U$21*U89 -> 5.9168349 | V23: =V$21*V89 -> 0.21107586 | W23: =W$21*W89 -> 0.42969015 | X23: =SUM(T23:W23) -> 11.735441 | AC23: =AC$21*AC89 -> 0 | AD23: =AD$21*AD89 -> 0 | AE23: =AE$21*AE89 -> 0 | AF23: =AF$21*AF89 -> 0 | AG23: =SUM(AC23:AF23) -> 0 | AI23: =AI$21*AI89 -> 29.755693 | AJ23: =AJ$21*AJ89 -> 34.002502 | AK23: =AK$21*AK89 -> 1.2129977 | AL23: =AL$21*AL89 -> 2.4693168 | AM23: =SUM(AI23:AL23) -> 67.44051 | AN23: =AG23+AM23 -> 67.44051
A24: 1-10 млн | G24: =G$21*G90 -> 284.56125 | H24: =H$21*H90 -> 171.58887 | I24: =I$21*I90 -> 7.8448274 | J24: =J$21*J90 -> 15.969827 | K24: =SUM(G24:J24) -> 479.96478 | N24: =N$21*N90 -> 417.75509 | O24: =O$21*O90 -> 251.90403 | P24: =P$21*P90 -> 11.516735 | Q24: =Q$21*Q90 -> 23.444782 | R24: =SUM(N24:Q24) -> 704.62064 | T24: =T$21*T90 -> 72.694296 | U24: =U$21*U90 -> 43.834262 | V24: =V$21*V90 -> 2.0040473 | W24: =W$21*W90 -> 4.0796677 | X24: =SUM(T24:W24) -> 122.61227 | AC24: =AC$21*AC90 -> 0 | AD24: =AD$21*AD90 -> 0 | AE24: =AE$21*AE90 -> 0 | AF24: =AF$21*AF90 -> 0 | AG24: =SUM(AC24:AF24) -> 0 | AI24: =AI$21*AI90 -> 417.75509 | AJ24: =AJ$21*AJ90 -> 251.90403 | AK24: =AK$21*AK90 -> 11.516735 | AL24: =AL$21*AL90 -> 23.444782 | AM24: =SUM(AI24:AL24) -> 704.62064 | AN24: =AG24+AM24 -> 704.62064
A25: менее 1 млн | G25: =G$21*G91 -> 2396.964 | H25: =H$21*H91 -> 932.02551 | I25: =I$21*I91 -> 53.528234 | J25: =J$21*J91 -> 108.96819 | K25: =SUM(G25:J25) -> 3491.4859 | N25: =N$21*N91 -> 3518.9046 | O25: =O$21*O91 -> 1368.2762 | P25: =P$21*P91 -> 78.583054 | Q25: =Q$21*Q91 -> 159.97265 | R25: =SUM(N25:Q25) -> 5125.7365 | T25: =T$21*T91 -> 612.33076 | U25: =U$21*U91 -> 238.09615 | V25: =V$21*V91 -> 13.674375 | W25: =W$21*W91 -> 27.837121 | X25: =SUM(T25:W25) -> 891.9384 | AC25: =AC$21*AC91 -> 612.33076 | AD25: =AD$21*AD91 -> 238.09615 | AE25: =AE$21*AE91 -> 13.674375 | AF25: =AF$21*AF91 -> 27.837121 | AG25: =SUM(AC25:AF25) -> 891.9384 | AI25: =AI$21*AI91 -> 0 | AJ25: =AJ$21*AJ91 -> 0 | AK25: =AK$21*AK91 -> 0 | AL25: =AL$21*AL91 -> 0 | AM25: =SUM(AI25:AL25) -> 0 | AN25: =AG25+AM25 -> 891.9384
A26: без оборотов | G26: =G$21*G92 -> 0 | H26: =H$21*H92 -> 0 | I26: =I$21*I92 -> 0 | J26: =J$21*J92 -> 0 | K26: =SUM(G26:J26) -> 0 | N26: =N$21*N92 -> 0 | O26: =O$21*O92 -> 0 | P26: =P$21*P92 -> 0 | Q26: =Q$21*Q92 -> 0 | R26: =SUM(N26:Q26) -> 0 | T26: =T$21*T92 -> 0 | U26: =U$21*U92 -> 0 | V26: =V$21*V92 -> 0 | W26: =W$21*W92 -> 0 | X26: =SUM(T26:W26) -> 0 | AC26: =AC$21*AC92 -> 0 | AD26: =AD$21*AD92 -> 0 | AE26: =AE$21*AE92 -> 0 | AF26: =AF$21*AF92 -> 0 | AG26: =SUM(AC26:AF26) -> 0 | AI26: =AI$21*AI92 -> 0 | AJ26: =AJ$21*AJ92 -> 0 | AK26: =AK$21*AK92 -> 0 | AL26: =AL$21*AL92 -> 0 | AM26: =SUM(AI26:AL26) -> 0 | AN26: =AG26+AM26 -> 0
M27: =M19/F19 -> 1.5
M28: =(M19-F19)/F19 -> 0.5
A29: LTV | G29: =G44/G21 -> 20930.298 | H29: =H44/H21 -> 21327.659 | I29: =I44/I21 -> 21106.467 | J29: =J44/J21 -> 21106.467 | K29: =K44/K21 -> 21050.155 | N29: =N44/N21 -> 23817.576 | O29: =O44/O21 -> 24219.665 | P29: =P44/P21 -> 23995.842 | Q29: =Q44/Q21 -> 23995.842 | R29: =R44/R21 -> 23938.859 | T29: =T44/T21 -> 23817.576 | U29: =U44/U21 -> 24219.665 | V29: =V44/V21 -> 23995.842 | W29: =W44/W21 -> 23995.842 | X29: =X44/X21 -> 23938.859 | AC29: =AC44/AC21 -> 23361.309 | AD29: =AD44/AD21 -> 23361.309 | AE29: =AE44/AE21 -> 23361.309 | AF29: =AF44/AF21 -> 23361.309 | AG29: =AG44/AG21 -> 23361.309 | AI29: =AI44/AI21 -> 27401.866 | AJ29: =AJ44/AJ21 -> 28286.923 | AK29: =AK44/AK21 -> 27889.878 | AL29: =AL44/AL21 -> 27889.878 | AM29: =AM44/AM21 -> 27755.848 | AN29: =AN44/AN21 -> 25405.252
A30: >100 млн | G30: =G45/G22 -> 55362.5 | H30: =H45/H22 -> 55362.5 | I30: =I45/I22 -> 55362.5 | J30: =J45/J22 -> 55362.5 | K30: =K45/K22 -> 55362.5 | N30: =N45/N22 -> 59174.344 | O30: =O45/O22 -> 59174.344 | P30: =P45/P22 -> 59174.344 | Q30: =Q45/Q22 -> 59174.344 | R30: =R45/R22 -> 59174.344 | T30: =T45/T22 -> 59174.344 | U30: =U45/U22 -> 59174.344 | V30: =V45/V22 -> 59174.344 | W30: =W45/W22 -> 59174.344 | X30: =X45/X22 -> 59174.344 | AC30: =AC45/AC22 -> #DIV/0! | AD30: =AD45/AD22 -> #DIV/0! | AE30: =AE45/AE22 -> #DIV/0! | AF30: =AF45/AF22 -> #DIV/0! | AG30: =AG45/AG22 -> #DIV/0! | AI30: =AI45/AI22 -> 59174.344 | AJ30: =AJ45/AJ22 -> 59174.344 | AK30: =AK45/AK22 -> 59174.344 | AL30: =AL45/AL22 -> 59174.344 | AM30: =AM45/AM22 -> 59174.344 | AN30: =AN45/AN22 -> 59174.344
A31: 10-100 млн | G31: =G46/G23 -> 35026.5 | H31: =H46/H23 -> 35026.5 | I31: =I46/I23 -> 35026.5 | J31: =J46/J23 -> 35026.5 | K31: =K46/K23 -> 35026.5 | N31: =N46/N23 -> 38183.395 | O31: =O46/O23 -> 38183.395 | P31: =P46/P23 -> 38183.395 | Q31: =Q46/Q23 -> 38183.395 | R31: =R46/R23 -> 38183.395 | T31: =T46/T23 -> 38183.395 | U31: =U46/U23 -> 38183.395 | V31: =V46/V23 -> 38183.395 | W31: =W46/W23 -> 38183.395 | X31: =X46/X23 -> 38183.395 | AC31: =AC46/AC23 -> #DIV/0! | AD31: =AD46/AD23 -> #DIV/0! | AE31: =AE46/AE23 -> #DIV/0! | AF31: =AF46/AF23 -> #DIV/0! | AG31: =AG46/AG23 -> #DIV/0! | AI31: =AI46/AI23 -> 38183.395 | AJ31: =AJ46/AJ23 -> 38183.395 | AK31: =AK46/AK23 -> 38183.395 | AL31: =AL46/AL23 -> 38183.395 | AM31: =AM46/AM23 -> 38183.395 | AN31: =AN46/AN23 -> 38183.395
A32: 1-10 млн | G32: =G47/G24 -> 23721.5 | H32: =H47/H24 -> 23721.5 | I32: =I47/I24 -> 23721.5 | J32: =J47/J24 -> 23721.5 | K32: =K47/K24 -> 23721.5 | N32: =N47/N24 -> 26600.988 | O32: =O47/O24 -> 26600.988 | P32: =P47/P24 -> 26600.988 | Q32: =Q47/Q24 -> 26600.988 | R32: =R47/R24 -> 26600.988 | T32: =T47/T24 -> 26600.988 | U32: =U47/U24 -> 26600.988 | V32: =V47/V24 -> 26600.988 | W32: =W47/W24 -> 26600.988 | X32: =X47/X24 -> 26600.988 | AC32: =AC47/AC24 -> #DIV/0! | AD32: =AD47/AD24 -> #DIV/0! | AE32: =AE47/AE24 -> #DIV/0! | AF32: =AF47/AF24 -> #DIV/0! | AG32: =AG47/AG24 -> #DIV/0! | AI32: =AI47/AI24 -> 26600.988 | AJ32: =AJ47/AJ24 -> 26600.988 | AK32: =AK47/AK24 -> 26600.988 | AL32: =AL47/AL24 -> 26600.988 | AM32: =AM47/AM24 -> 26600.988 | AN32: =AN47/AN24 -> 26600.988
A33: менее 1 млн | G33: =G48/G25 -> 20475.5 | H33: =H48/H25 -> 20475.5 | I33: =I48/I25 -> 20475.5 | J33: =J48/J25 -> 20475.5 | K33: =K48/K25 -> 20475.5 | N33: =N48/N25 -> 23361.309 | O33: =O48/O25 -> 23361.309 | P33: =P48/P25 -> 23361.309 | Q33: =Q48/Q25 -> 23361.309 | R33: =R48/R25 -> 23361.309 | T33: =T48/T25 -> 23361.309 | U33: =U48/U25 -> 23361.309 | V33: =V48/V25 -> 23361.309 | W33: =W48/W25 -> 23361.309 | X33: =X48/X25 -> 23361.309 | AC33: =AC48/AC25 -> 23361.309 | AD33: =AD48/AD25 -> 23361.309 | AE33: =AE48/AE25 -> 23361.309 | AF33: =AF48/AF25 -> 23361.309 | AG33: =AG48/AG25 -> 23361.309 | AI33: =AI48/AI25 -> #DIV/0! | AJ33: =AJ48/AJ25 -> #DIV/0! | AK33: =AK48/AK25 -> #DIV/0! | AL33: =AL48/AL25 -> #DIV/0! | AM33: =AM48/AM25 -> #DIV/0! | AN33: =AN48/AN25 -> 23361.309
A34: без оборотов
A35: Расходы на 1 платящего клиента | G35: =G36+G40+G41 -> 17257.06 | H35: =H36+H40+H41 -> 17274.489 | I35: =I36+I40+I41 -> 17264.787 | J35: =J36+J40+J41 -> 17264.787 | K35: =K36+K40+K41 -> 17262.317 | N35: =N50/N21 -> 10573.405 | O35: =O50/O21 -> 10590.834 | P35: =P50/P21 -> 10581.132 | Q35: =Q50/Q21 -> 10581.132 | R35: =R50/R21 -> 10578.662 | T35: =T50/T21 -> 5327.4925 | U35: =U50/U21 -> 5344.9216 | V35: =V50/V21 -> 5335.2196 | W35: =W50/W21 -> 5335.2196 | X35: =X50/X21 -> 5332.7497 | AC35: =AC50/AC21 -> 5305.0586 | AD35: =AD50/AD21 -> 5305.0586 | AE35: =AE50/AE21 -> 5305.0586 | AF35: =AF50/AF21 -> 5305.0586 | AG35: =AG50/AG21 -> 5305.0586 | AI35: =AI50/AI21 -> 10658.804 | AJ35: =AJ50/AJ21 -> 10688.887 | AK35: =AK50/AK21 -> 10675.392 | AL35: =AL50/AL21 -> 10675.392 | AM35: =AM50/AM21 -> 10670.836 | AN35: =AN50/AN21 -> 7800.7337
A36: CAC | G36: =SUM(G37:G39) -> 14406.632 | H36: =SUM(H37:H39) -> 14406.632 | I36: =SUM(I37:I39) -> 14406.632 | J36: =SUM(J37:J39) -> 14406.632 | K36: =SUM(K37:K39) -> 14406.632 | N36: =SUM(N37:N39) -> 9619.0183 | O36: =SUM(O37:O39) -> 9619.0183 | P36: =SUM(P37:P39) -> 9619.0183 | Q36: =SUM(Q37:Q39) -> 9619.0183 | R36: =SUM(R37:R39) -> 9619.0183 | T36: =SUM(T37:T39) -> 3940.4519 | U36: =SUM(U37:U39) -> 3940.4519 | V36: =SUM(V37:V39) -> 3940.4519 | W36: =SUM(W37:W39) -> 3940.4519 | X36: =SUM(X37:X39) -> 3940.4519 | AC36: =SUM(AC37:AC39) -> 3940.4519 | AD36: =SUM(AD37:AD39) -> 3940.4519 | AE36: =SUM(AE37:AE39) -> 3940.4519 | AF36: =SUM(AF37:AF39) -> 3940.4519 | AG36: =SUM(AG37:AG39) -> 3940.4519 | AI36: =SUM(AI37:AI39) -> 9619.0183 | AJ36: =SUM(AJ37:AJ39) -> 9619.0183 | AK36: =SUM(AK37:AK39) -> 9619.0183 | AL36: =SUM(AL37:AL39) -> 9619.0183 | AM36: =SUM(AM37:AM39) -> 9619.0183 | AN36: =AN51/AN21 -> 6400.8544
A37: Sales, КЦ | G37: =G52/G19 -> 13400 | H37: =H52/H19 -> 13400 | I37: =I52/I19 -> 13400 | J37: =J52/J19 -> 13400 | K37: =K52/K19 -> 13400 | N37: =N52/N19 -> 8933.3333 | O37: =O52/O19 -> 8933.3333 | P37: =P52/P19 -> 8933.3333 | Q37: =Q52/Q19 -> 8933.3333 | R37: =R52/R19 -> 8933.3333 | T37: =T52/T19 -> 0 | U37: =U52/U19 -> 0 | V37: =V52/V19 -> 0 | W37: =W52/W19 -> 0 | X37: =X52/X19 -> 0 | AC37: =AC52/AC19 -> 0 | AD37: =AD52/AD19 -> 0 | AE37: =AE52/AE19 -> 0 | AF37: =AF52/AF19 -> 0 | AG37: =AG52/AG19 -> 0 | AI37: =AI52/AI19 -> 8933.3333 | AJ37: =AJ52/AJ19 -> 8933.3333 | AK37: =AK52/AK19 -> 8933.3333 | AL37: =AL52/AL19 -> 8933.3333 | AM37: =AM52/AM19 -> 8933.3333
A38: маркетинг Т внешний | G38: =G54/G21 -> 746.30864 | H38: =H54/H21 -> 746.30864 | I38: =I54/I21 -> 746.30864 | J38: =J54/J21 -> 746.30864 | K38: =K54/K21 -> 746.30864 | N38: =N54/N21 -> 508.3613 | O38: =O54/O21 -> 508.3613 | P38: =P54/P21 -> 508.3613 | Q38: =Q54/Q21 -> 508.3613 | R38: =R54/R21 -> 508.3613 | T38: =T54/T21 -> 2921.4193 | U38: =U54/U21 -> 2921.4193 | V38: =V54/V21 -> 2921.4193 | W38: =W54/W21 -> 2921.4193 | X38: =X54/X21 -> 2921.4193 | AC38: =AC54/AC21 -> 2921.4193 | AD38: =AD54/AD21 -> 2921.4193 | AE38: =AE54/AE21 -> 2921.4193 | AF38: =AF54/AF21 -> 2921.4193 | AG38: =AG54/AG21 -> 2921.4193 | AI38: =AI54/AI21 -> 508.3613 | AJ38: =AJ54/AJ21 -> 508.3613 | AK38: =AK54/AK21 -> 508.3613 | AL38: =AL54/AL21 -> 508.3613 | AM38: =AM54/AM21 -> 508.3613
A39: триал | G39: =G53/G21 -> 260.32305 | H39: =H53/H21 -> 260.32305 | I39: =I53/I21 -> 260.32305 | J39: =J53/J21 -> 260.32305 | K39: =K53/K21 -> 260.32305 | N39: =N53/N21 -> 177.32364 | O39: =O53/O21 -> 177.32364 | P39: =P53/P21 -> 177.32364 | Q39: =Q53/Q21 -> 177.32364 | R39: =R53/R21 -> 177.32364 | T39: =T53/T21 -> 1019.0325 | U39: =U53/U21 -> 1019.0325 | V39: =V53/V21 -> 1019.0325 | W39: =W53/W21 -> 1019.0325 | X39: =X53/X21 -> 1019.0325 | AC39: =AC53/AC21 -> 1019.0325 | AD39: =AD53/AD21 -> 1019.0325 | AE39: =AE53/AE21 -> 1019.0325 | AF39: =AF53/AF21 -> 1019.0325 | AG39: =AG53/AG21 -> 1019.0325 | AI39: =AI53/AI21 -> 177.32364 | AJ39: =AJ53/AJ21 -> 177.32364 | AK39: =AK53/AK21 -> 177.32364 | AL39: =AL53/AL21 -> 177.32364 | AM39: =AM53/AM21 -> 177.32364
A40: API | G40: =G55/G21 -> 1250.4282 | H40: =H55/H21 -> 1267.8573 | I40: =I55/I21 -> 1258.1554 | J40: =J55/J21 -> 1258.1554 | K40: =K55/K21 -> 1255.6854 | N40: =N55/N21 -> 1343.0131 | O40: =O55/O21 -> 1360.4421 | P40: =P55/P21 -> 1350.7402 | Q40: =Q55/Q21 -> 1350.7402 | R40: =R55/R21 -> 1348.2703 | T40: =T55/T21 -> 1387.0406 | U40: =U55/U21 -> 1404.4697 | V40: =V55/V21 -> 1394.7678 | W40: =W55/W21 -> 1394.7678 | X40: =X55/X21 -> 1392.2978 | AC40: =AC55/AC21 -> 1364.6068 | AD40: =AD55/AD21 -> 1364.6068 | AE40: =AE55/AE21 -> 1364.6068 | AF40: =AF55/AF21 -> 1364.6068 | AG40: =AG55/AG21 -> 1364.6068 | AI40: =AI55/AI21 -> 1428.4118 | AJ40: =AJ55/AJ21 -> 1458.4952 | AK40: =AK55/AK21 -> 1444.9995 | AL40: =AL55/AL21 -> 1444.9995 | AM40: =AM55/AM21 -> 1440.4438 | AN40: =AN55/AN21 -> 1399.8793
...

Sheet Гипотезы_v3
F1: Биллинг MPS | L1: Биллинг Т-Банк | S1: Биллинг Т-Банк | AB1: Биллинг Т-Банк
F2: Гипотеза 1. Sales MPS + Биллинг MPS | M2: Гипотеза 2. Sales MPS + Биллинг Т | S2: Гипотеза 3.Digital + Биллинг Т | AB2: Гипотеза 4. Digital + Sales MPS (> 1млн) + Биллинг Т
AB3: Digital (до 1 млн оборот) | AH3: Sales (>1 млн оборот)
A4: Воронка | B4: Конверсии как дали MPStats | C4: Конверсии как дали MPStats | D4: От какого этапа | E4: От всех лидов | F4: Конверсии | G4: Сегмент 1. Активные клиенты в Т с выплатами от МП. 1 приоритет | H4: Сегмент 2. Активные клиенты в Т., но без выплат от МП на РКО. | I4: Сегмент 3. Спящие клиенты в Т (нет транзакций по РКО). Проснулись | J4: Сегмент 4. Клиенты без РКО в Т - Рынок. Открыли РКО | K4: ALL | L4: От всех лидов | M4: Конверсии | N4: Сегмент 1. Активные селлеры в Т с выплатами от МП. 1 приоритет | O4: Сегмент 2. Активные селлеры в Т., но без выплат от МП | P4: Сегмент 3. Спящие селлеры в Т (нет транзакций по РКО) | Q4: Сегмент 4. Селлеры без РКО в Т - Рынок | R4: ALL | S4: Конверсии | T4: Сегмент 1. Активные селлеры в Т с выплатами от МП. 1 приоритет | U4: Сегмент 2. Активные селлеры в Т., но без выплат от МП | V4: Сегмент 3. Спящие селлеры в Т (нет транзакций по РКО) | W4: Сегмент 4. Селлеры без РКО в Т - Рынок | X4: ALL | Y4: От все Лиды Digital | Z4: От все Лиды Sales | AA4: От все Лиды | AB4: Конверсии | AC4: Сегмент 1. Активные селлеры в Т с выплатами от МП. 1 приоритет | AD4: Сегмент 2. Активные селлеры в Т., но без выплат от МП | AE4: Сегмент 3. Спящие селлеры в Т (нет транзакций по РКО) | AF4: Сегмент 4. Селлеры без РКО в Т - Рынок | AG4: ALL Digital | AH4: Конверсии | AI4: Сегмент 1. Активные селлеры в Т с выплатами от МП. 1 приоритет | AJ4: Сегмент 2. Активные селлеры в Т., но без выплат от МП | AK4: Сегмент 3. Спящие селлеры в Т (нет транзакций по РКО) | AL4: Сегмент 4. Селлеры без РКО в Т - Рынок | AM4: ALL Sales | AN4: ALL
A5: База селлеров | F5: 1 | G5: ='База селлеров'!B63 -> 79000 | H5: ='База селлеров'!C63 -> 33000 | I5: ='База селлеров'!D67 -> 1820 | J5: ='База селлеров'!E67 -> 3705 | K5: =SUM(G5:J5) -> 117525 | M5: =F5 -> 1 | N5: =G5 -> 79000 | O5: =H5 -> 33000 | P5: =I5 -> 1820 | Q5: =J5 -> 3705 | R5: =SUM(N5:Q5) -> 117525 | S5: =M5 -> 1 | T5: =N5 -> 79000 | U5: =O5 -> 33000 | V5: =P5 -> 1820 | W5: =Q5 -> 3705 | X5: =SUM(T5:W5) -> 117525 | AC5: =T5*T88 -> 70079.175 | AD5: =U5*U88 -> 27249.295 | AE5: =V5*V88 -> 1564.9858 | AF5: =W5*W88 -> 3185.8639 | AG5: =SUM(AC5:AF5) -> 102079.32 | AI5: =T5-AC5 -> 8920.8253 | AJ5: =U5-AD5 -> 5750.7049 | AK5: =V5-AE5 -> 255.01424 | AL5: =W5-AF5 -> 519.13612 | AM5: =SUM(AI5:AL5) -> 15445.681 | AN5: =AG5+AM5 -> 117525 | AV5: =T5 -> 79000 | AW5: =U5 -> 33000 | AX5: =V5 -> 1820 | AY5: =W5 -> 3705 | AZ5: =X5 -> 117525
A6: Увеличение базы - влияние MPStast | I6: ='База селлеров'!D69 -> 130 | J6: ='База селлеров'!E69 -> 1233 | P6: =I6 -> 130 | Q6: =J6 -> 1233 | V6: =P6 -> 130 | W6: =Q6 -> 1233 | AE6: =V6*V88 -> 111.7847 | AF6: =W6*W88 -> 1060.2349 | AK6: =V6-AE6 -> 18.215303 | AL6: =W6-AF6 -> 172.76514
A7: Лиды (визиты Селлер) | C7: 1 | D7: от Базы | F7: 0.8 | G7: =G5*$F$7 -> 63200 | H7: =H5*$F$7 -> 26400 | I7: =I5*$F$7 -> 1456 | J7: =J5*$F$7 -> 2964 | K7: =SUM(G7:J7) -> 94020 | M7: =F7 -> 0.8 | N7: =G7 -> 63200 | O7: =H7 -> 26400 | P7: =I7 -> 1456 | Q7: =J7 -> 2964 | R7: =SUM(N7:Q7) -> 94020 | S7: =M7 -> 0.8 | T7: =N7 -> 63200 | U7: =O7 -> 26400 | V7: =P7 -> 1456 | W7: =Q7 -> 2964 | X7: =SUM(T7:W7) -> 94020 | AB7: =S7 -> 0.8 | AC7: =$AB$7*AC5 -> 56063.34 | AD7: =$AB$7*AD5 -> 21799.436 | AE7: =$AB$7*AE5 -> 1251.9886 | AF7: =$AB$7*AF5 -> 2548.6911 | AG7: =SUM(AC7:AF7) -> 81663.456 | AH7: =M7 -> 0.8 | AI7: =$AH$7*AI5 -> 7136.6602 | AJ7: =$AH$7*AJ5 -> 4600.5639 | AK7: =$AH$7*AK5 -> 204.01139 | AL7: =$AH$7*AL5 -> 415.3089 | AM7: =SUM(AI7:AL7) -> 12356.544 | AN7: =AG7+AM7 -> 94020 | AY7: =AY5 -> 3705 | AZ7: =AZ5 -> 117525
A8: Оставление API ключа
A9: Оффер триала
A10: Триала выдан
A11: Активация триала
A12: Активация в Селлере
A13: Квалификацированные лиды ЦА (не дозвон КЦ) | D13: от Лиды | F13: =G13/G7 -> 0.25 | G13: =G7-G14 -> 15800 | H13: =H7-H14 -> 6600 | I13: =I7-I14 -> 364 | J13: =J7-J14 -> 741 | K13: =SUM(G13:J13) -> 23505 | M13: =N13/N7 -> 0.25 | N13: =N7-N14 -> 15800 | O13: =O7-O14 -> 6600 | P13: =P7-P14 -> 364 | Q13: =Q7-Q14 -> 741 | R13: =SUM(N13:Q13) -> 23505 | S13: - | T13: - | U13: - | V13: - | W13: - | X13: - | AH13: =M13 -> 0.25 | AI13: =AI7-AI14 -> 1784.1651 | AJ13: =AJ7-AJ14 -> 1150.141 | AK13: =AK7-AK14 -> 51.002847 | AL13: =AL7-AL14 -> 103.82722 | AM13: =SUM(AI13:AL13) -> 3089.1361 | AN13: =AG13+AM13 -> 3089.1361
A14: Квалификацированные лиды ЦА (дозвоны) | B14: от Лиды | C14: 0.13 | D14: от Лиды | F14: 0.75 | G14: =$G$7*F14 -> 47400 | H14: =$H$7*F14 -> 19800 | I14: =$I$7*F14 -> 1092 | J14: =$J$7*F14 -> 2223 | K14: =SUM(G14:J14) -> 70515 | M14: =F14 -> 0.75 | N14: =$N$7*M14 -> 47400 | O14: =$O$7*M14 -> 19800 | P14: =$P$7*M14 -> 1092 | Q14: =$Q$7*M14 -> 2223 | R14: =SUM(N14:Q14) -> 70515 | S14: - | T14: - | U14: - | V14: - | W14: - | X14: - | AH14: =M14 -> 0.75 | AI14: =$AI$7*AH14 -> 5352.4952 | AJ14: =$AJ$7*AH14 -> 3450.4229 | AK14: =$AK$7*AH14 -> 153.00854 | AL14: =$AL$7*AH14 -> 311.48167 | AM14: =SUM(AI14:AL14) -> 9267.4083 | AN14: =AG14+AM14 -> 9267.4083
A15: /Оффер демо встречи | B15: от Квалиф. Лиды | C15: 1 | D15: от Квал. Лиды | F15: 1 | G15: =$G$14*F15 -> 47400 | H15: =$H$14*F15 -> 19800 | I15: =$I$14*F15 -> 1092 | J15: =$J$14*F15 -> 2223 | K15: =SUM(G15:J15) -> 70515 | M15: =F15 -> 1 | N15: =$N$7*M15 -> 63200 | O15: =$O$7*M15 -> 26400 | P15: =$P$7*M15 -> 1456 | Q15: =$Q$7*M15 -> 2964 | R15: =SUM(N15:Q15) -> 94020 | S15: - | T15: - | U15: - | V15: - | W15: - | X15: - | AH15: =M15 -> 1 | AI15: =$AI$7*AH15 -> 7136.6602 | AJ15: =$AJ$7*AH15 -> 4600.5639 | AK15: =$AK$7*AH15 -> 204.01139 | AL15: =$AL$7*AH15 -> 415.3089 | AM15: =SUM(AI15:AL15) -> 12356.544 | AN15: =AG15+AM15 -> 12356.544
A16: //Согласились на демо встречу | B16: от Квалиф. Лиды | C16: 0.4 | D16: от Квал. Лиды | F16: ='Воронка MPS_обработано'!N10 -> 0.4 | G16: =$G$14*F16 -> 18960 | H16: =$H$14*F16 -> 7920 | I16: =$I$14*F16 -> 436.8 | J16: =$J$14*F16 -> 889.2 | K16: =SUM(G16:J16) -> 28206 | M16: =F16 -> 0.4 | N16: =$N$7*M16 -> 25280 | O16: =$O$7*M16 -> 10560 | P16: =$P$7*M16 -> 582.4 | Q16: =$Q$7*M16 -> 1185.6 | R16: =SUM(N16:Q16) -> 37608 | S16: - | T16: - | U16: - | V16: - | W16: - | X16: - | AH16: =M16 -> 0.4 | AI16: =$AI$7*AH16 -> 2854.6641 | AJ16: =$AJ$7*AH16 -> 1840.2256 | AK16: =$AK$7*AH16 -> 81.604556 | AL16: =$AL$7*AH16 -> 166.12356 | AM16: =SUM(AI16:AL16) -> 4942.6178 | AN16: =AG16+AM16 -> 4942.6178
A17: //Демо встреча состоялась | B17: от Квалиф. Лиды | C17: 0.298 | D17: от Квал. Лиды | F17: ='Воронка MPS_обработано'!N11 -> 0.298 | G17: =$G$14*F17 -> 14125.2 | H17: =$H$14*F17 -> 5900.4 | I17: =$I$14*F17 -> 325.416 | J17: =$J$14*F17 -> 662.454 | K17: =SUM(G17:J17) -> 21013.47 | M17: =F17 -> 0.298 | N17: =$N$7*M17 -> 18833.6 | O17: =$O$7*M17 -> 7867.2 | P17: =$P$7*M17 -> 433.888 | Q17: =$Q$7*M17 -> 883.272 | R17: =SUM(N17:Q17) -> 28017.96 | S17: - | T17: - | U17: - | V17: - | W17: - | X17: - | AH17: =M17 -> 0.298 | AI17: =$AI$7*AH17 -> 2126.7247 | AJ17: =$AJ$7*AH17 -> 1370.968 | AK17: =$AK$7*AH17 -> 60.795394 | AL17: =$AL$7*AH17 -> 123.76205 | AM17: =SUM(AI17:AL17) -> 3682.2502 | AN17: =AG17+AM17 -> 3682.2502
A18: /Дозвон sales (кто не согласился на демо) | B18: от Квалиф. Лиды | C18: 0.455 | D18: от Квал. Лиды | F18: ='Воронка MPS_обработано'!N12 -> 0.455 | G18: =$G$14*F18 -> 21567 | H18: =$H$14*F18 -> 9009 | I18: =$I$14*F18 -> 496.86 | J18: =$J$14*F18 -> 1011.465 | K18: =SUM(G18:J18) -> 32084.325 | M18: =F18 -> 0.455 | N18: =$N$7*M18 -> 28756 | O18: =$O$7*M18 -> 12012 | P18: =$P$7*M18 -> 662.48 | Q18: =$Q$7*M18 -> 1348.62 | R18: =SUM(N18:Q18) -> 42779.1 | S18: - | T18: - | U18: - | V18: - | W18: - | X18: - | AH18: =M18 -> 0.455 | AI18: =$AI$7*AH18 -> 3247.1804 | AJ18: =$AJ$7*AH18 -> 2093.2566 | AK18: =$AK$7*AH18 -> 92.825182 | AL18: =$AL$7*AH18 -> 188.96555 | AM18: =SUM(AI18:AL18) -> 5622.2277 | AN18: =AG18+AM18 -> 5622.2277
A19: Покупка тарифа MPS (основной канал) | B19: от Лиды | C19: 0,7% / 0,41%/ 1,1% всего | D19: от Квал. Лиды | E19: =K19/K7 -> 0.064038462 | F19: ='Воронка MPS_обработано'!N14 -> 0.085384615 | G19: =$G$14*F19 -> 4047.2308 | H19: =$H$14*F19 -> 1690.6154 | I19: =$I$14*F19 -> 93.24 | J19: =$J$14*F19 -> 189.81 | K19: =SUM(G19:J19) -> 6020.8962 | L19: =R19/R7 -> 0.096057692 | M19: =F19*1.5 -> 0.12807692 | N19: =N14*$M$19 -> 6070.8462 | O19: =O14*$M$19 -> 2535.9231 | P19: =P14*$M$19 -> 139.86 | Q19: =Q14*$M$19 -> 284.715 | R19: =SUM(N19:Q19) -> 9031.3442 | S19: ='Воронка Селлер as is'!F12 -> 0.017475399 | T19: =$S$19*T7 -> 1104.4452 | U19: =$S$19*U7 -> 461.35053 | V19: =$S$19*V7 -> 25.444181 | W19: =$S$19*W7 -> 51.797082 | X19: =SUM(T19:W19) -> 1643.037 | Y19: =AG19/$AG$7 -> 0.017475399 | Z19: =AM19/$AM$7 -> 0.096057692 | AA19: =AN19/AN7 -> 0.027803048 | AB19: =S19 -> 0.017475399 | AC19: =$S$19*AC7 -> 979.72922 | AD19: =$S$19*AD7 -> 380.95384 | AE19: =$S$19*AE7 -> 21.879 | AF19: =$S$19*AF7 -> 44.539393 | AG19: =SUM(AC19:AF19) -> 1427.1014 | AH19: =M19 -> 0.12807692 | AI19: =AI14*$AH$19 -> 685.53111 | AJ19: =AJ14*$AH$19 -> 441.91955 | AK19: =AK14*$AH$19 -> 19.596863 | AL19: =AL14*$AH$19 -> 39.893614 | AM19: =SUM(AI19:AL19) -> 1186.9411 | AN19: =AG19+AM19 -> 2614.0426
A20: Покупка тарифа MPS (самоходы) | D20: от Лиды | E20: =K20/K7 -> 0.0043688497 | F20: =S19 -> 0.017475399 | G20: =G13*$F$20 -> 276.1113 | H20: =H13*$F$20 -> 115.33763 | I20: =I13*$F$20 -> 6.3610451 | J20: =J13*$F$20 -> 12.94927 | K20: =SUM(G20:J20) -> 410.75925 | L20: =R20/R7 -> 0.0043688497 | M20: =S19 -> 0.017475399 | N20: =N13*$M$20 -> 276.1113 | O20: =O13*$M$20 -> 115.33763 | P20: =P13*$M$20 -> 6.3610451 | Q20: =Q13*$M$20 -> 12.94927 | R20: =SUM(N20:Q20) -> 410.75925 | Y20: =AG20/$AG$7 -> 0 | Z20: =AM20/$AM$7 -> 0.0043688497 | AA20: =AN20/AN7 -> 0.00057417449 | AH20: =M20 -> 0.017475399 | AI20: =AI13*$AH$20 -> 31.178996 | AJ20: =AJ13*$AH$20 -> 20.099172 | AK20: =AK13*$AH$20 -> 0.89129509 | AL20: =AL13*$AH$20 -> 1.8144222 | AM20: =SUM(AI20:AL20) -> 53.983885 | AN20: =AG20+AM20 -> 53.983885
A21: Покупка тарифа MPS (всего) | E21: =K21/K7 -> 0.068407311 | G21: =SUM(G19:G20) -> 4323.3421 | H21: =SUM(H19:H20) -> 1805.953 | I21: =SUM(I19:I20) -> 99.601045 | J21: =SUM(J19:J20) -> 202.75927 | K21: =SUM(G21:J21) -> 6431.6554 | L21: =R21/R7 -> 0.10042654 | N21: =SUM(N19:N20) -> 6346.9575 | O21: =SUM(O19:O20) -> 2651.2607 | P21: =SUM(P19:P20) -> 146.22105 | Q21: =SUM(Q19:Q20) -> 297.66427 | R21: =SUM(N21:Q21) -> 9442.1035 | T21: =T19 -> 1104.4452 | U21: =U19 -> 461.35053 | V21: =V19 -> 25.444181 | W21: =W19 -> 51.797082 | X21: =SUM(T21:W21) -> 1643.037 | Y21: =AG21/$AG$7 -> 0.017475399 | Z21: =AM21/$AM$7 -> 0.10042654 | AA21: =AN21/AN7 -> 0.028377223 | AC21: =AC19 -> 979.72922 | AD21: =AD19 -> 380.95384 | AE21: =AE19 -> 21.879 | AF21: =AF19 -> 44.539393 | AG21: =SUM(AC21:AF21) -> 1427.1014 | AI21: =SUM(AI19:AI20) -> 716.71011 | AJ21: =SUM(AJ19:AJ20) -> 462.01872 | AK21: =SUM(AK19:AK20) -> 20.488158 | AL21: =SUM(AL19:AL20) -> 41.708037 | AM21: =SUM(AI21:AL21) -> 1240.925 | AN21: =AG21+AM21 -> 2668.0265
A22: >100 млн | G22: =G$21*G85 -> 0.47195113 | H22: =H$21*H85 -> 3.1117611 | I22: =I$21*I85 -> 0.082139131 | J22: =J$21*J85 -> 0.1672118 | K22: =SUM(G22:J22) -> 3.8330632 | N22: =N$21*N85 -> 0.69285606 | O22: =O$21*O85 -> 4.568275 | P22: =P$21*P85 -> 0.12058578 | Q22: =Q$21*Q85 -> 0.24547819 | R22: =SUM(N22:Q22) -> 5.6271951 | T22: =T$21*T85 -> 0.1205651 | U22: =U$21*U85 -> 0.79493355 | V22: =V$21*V85 -> 0.020983343 | W22: =W$21*W85 -> 0.042716091 | X22: =SUM(T22:W22) -> 0.97919808 | AC22: =AC$21*AC85 -> 0 | AD22: =AD$21*AD85 -> 0 | AE22: =AE$21*AE85 -> 0 | AF22: =AF$21*AF85 -> 0 | AG22: =SUM(AC22:AF22) -> 0 | AI22: =AI$21*AI85 -> 0.69285606 | AJ22: =AJ$21*AJ85 -> 4.568275 | AK22: =AK$21*AK85 -> 0.12058578 | AL22: =AL$21*AL85 -> 0.24547819 | AM22: =SUM(AI22:AL22) -> 5.6271951 | AN22: =AG22+AM22 -> 5.6271951
A23: 10-100 млн | G23: =G$21*G86 -> 32.429785 | H23: =H$21*H86 -> 37.058246 | I23: =I$21*I86 -> 1.3220077 | J23: =J$21*J86 -> 2.6912299 | K23: =SUM(G23:J23) -> 73.501269 | N23: =N$21*N86 -> 47.609109 | O23: =O$21*O86 -> 54.404003 | P23: =P$21*P86 -> 1.9407964 | Q23: =Q$21*Q86 -> 3.9509069 | R23: =SUM(N23:Q23) -> 107.90482 | T23: =T$21*T86 -> 8.2845446 | U23: =U$21*U86 -> 9.4669359 | V23: =V$21*V86 -> 0.33772138 | W23: =W$21*W86 -> 0.68750424 | X23: =SUM(T23:W23) -> 18.776706 | AC23: =AC$21*AC86 -> 0 | AD23: =AD$21*AD86 -> 0 | AE23: =AE$21*AE86 -> 0 | AF23: =AF$21*AF86 -> 0 | AG23: =SUM(AC23:AF23) -> 0 | AI23: =AI$21*AI86 -> 47.609109 | AJ23: =AJ$21*AJ86 -> 54.404003 | AK23: =AK$21*AK86 -> 1.9407964 | AL23: =AL$21*AL86 -> 3.9509069 | AM23: =SUM(AI23:AL23) -> 107.90482 | AN23: =AG23+AM23 -> 107.90482
A24: 1-10 млн | G24: =G$21*G87 -> 455.298 | H24: =H$21*H87 -> 274.5422 | I24: =I$21*I87 -> 12.551724 | J24: =J$21*J87 -> 25.551723 | K24: =SUM(G24:J24) -> 767.94365 | N24: =N$21*N87 -> 668.40814 | O24: =O$21*O87 -> 403.04645 | P24: =P$21*P87 -> 18.426776 | Q24: =Q$21*Q87 -> 37.511652 | R24: =SUM(N24:Q24) -> 1127.393 | T24: =T$21*T87 -> 116.31087 | U24: =U$21*U87 -> 70.134819 | V24: =V$21*V87 -> 3.2064756 | W24: =W$21*W87 -> 6.5274683 | X24: =SUM(T24:W24) -> 196.17964 | AC24: =AC$21*AC87 -> 0 | AD24: =AD$21*AD87 -> 0 | AE24: =AE$21*AE87 -> 0 | AF24: =AF$21*AF87 -> 0 | AG24: =SUM(AC24:AF24) -> 0 | AI24: =AI$21*AI87 -> 668.40814 | AJ24: =AJ$21*AJ87 -> 403.04645 | AK24: =AK$21*AK87 -> 18.426776 | AL24: =AL$21*AL87 -> 37.511652 | AM24: =SUM(AI24:AL24) -> 1127.393 | AN24: =AG24+AM24 -> 1127.393
A25: менее 1 млн | G25: =G$21*G88 -> 3835.1423 | H25: =H$21*H88 -> 1491.2408 | I25: =I$21*I88 -> 85.645175 | J25: =J$21*J88 -> 174.34911 | K25: =SUM(G25:J25) -> 5586.3774 | N25: =N$21*N88 -> 5630.2473 | O25: =O$21*O88 -> 2189.242 | P25: =P$21*P88 -> 125.73289 | Q25: =Q$21*Q88 -> 255.95623 | R25: =SUM(N25:Q25) -> 8201.1785 | T25: =T$21*T88 -> 979.72922 | U25: =U$21*U88 -> 380.95384 | V25: =V$21*V88 -> 21.879 | W25: =W$21*W88 -> 44.539393 | X25: =SUM(T25:W25) -> 1427.1014 | AC25: =AC$21*AC88 -> 979.72922 | AD25: =AD$21*AD88 -> 380.95384 | AE25: =AE$21*AE88 -> 21.879 | AF25: =AF$21*AF88 -> 44.539393 | AG25: =SUM(AC25:AF25) -> 1427.1014 | AI25: =AI$21*AI88 -> 0 | AJ25: =AJ$21*AJ88 -> 0 | AK25: =AK$21*AK88 -> 0 | AL25: =AL$21*AL88 -> 0 | AM25: =SUM(AI25:AL25) -> 0 | AN25: =AG25+AM25 -> 1427.1014
A26: без оборотов | G26: =G$21*G89 -> 0 | H26: =H$21*H89 -> 0 | I26: =I$21*I89 -> 0 | J26: =J$21*J89 -> 0 | K26: =SUM(G26:J26) -> 0 | N26: =N$21*N89 -> 0 | O26: =O$21*O89 -> 0 | P26: =P$21*P89 -> 0 | Q26: =Q$21*Q89 -> 0 | R26: =SUM(N26:Q26) -> 0 | T26: =T$21*T89 -> 0 | U26: =U$21*U89 -> 0 | V26: =V$21*V89 -> 0 | W26: =W$21*W89 -> 0 | X26: =SUM(T26:W26) -> 0 | AC26: =AC$21*AC89 -> 0 | AD26: =AD$21*AD89 -> 0 | AE26: =AE$21*AE89 -> 0 | AF26: =AF$21*AF89 -> 0 | AG26: =SUM(AC26:AF26) -> 0 | AI26: =AI$21*AI89 -> 0 | AJ26: =AJ$21*AJ89 -> 0 | AK26: =AK$21*AK89 -> 0 | AL26: =AL$21*AL89 -> 0 | AM26: =SUM(AI26:AL26) -> 0 | AN26: =AG26+AM26 -> 0
M27: =M19/F19 -> 1.5
M28: =(M19-F19)/F19 -> 0.5
A29: LTV | G29: =G44/G21 -> 20930.298 | H29: =H44/H21 -> 21327.659 | I29: =I44/I21 -> 21106.467 | J29: =J44/J21 -> 21106.467 | K29: =K44/K21 -> 21050.155 | N29: =N44/N21 -> 23817.576 | O29: =O44/O21 -> 24219.665 | P29: =P44/P21 -> 23995.842 | Q29: =Q44/Q21 -> 23995.842 | R29: =R44/R21 -> 23938.859 | T29: =T44/T21 -> 23817.576 | U29: =U44/U21 -> 24219.665 | V29: =V44/V21 -> 23995.842 | W29: =W44/W21 -> 23995.842 | X29: =X44/X21 -> 23938.859 | AC29: =AC44/AC21 -> 23361.309 | AD29: =AD44/AD21 -> 23361.309 | AE29: =AE44/AE21 -> 23361.309 | AF29: =AF44/AF21 -> 23361.309 | AG29: =AG44/AG21 -> 23361.309 | AI29: =AI44/AI21 -> 27401.866 | AJ29: =AJ44/AJ21 -> 28286.923 | AK29: =AK44/AK21 -> 27889.878 | AL29: =AL44/AL21 -> 27889.878 | AM29: =AM44/AM21 -> 27755.848 | AN29: =AN44/AN21 -> 25405.252
A30: >100 млн | G30: =G45/G22 -> 55362.5 | H30: =H45/H22 -> 55362.5 | I30: =I45/I22 -> 55362.5 | J30: =J45/J22 -> 55362.5 | K30: =K45/K22 -> 55362.5 | N30: =N45/N22 -> 59174.344 | O30: =O45/O22 -> 59174.344 | P30: =P45/P22 -> 59174.344 | Q30: =Q45/Q22 -> 59174.344 | R30: =R45/R22 -> 59174.344 | T30: =T45/T22 -> 59174.344 | U30: =U45/U22 -> 59174.344 | V30: =V45/V22 -> 59174.344 | W30: =W45/W22 -> 59174.344 | X30: =X45/X22 -> 59174.344 | AC30: =AC45/AC22 -> #DIV/0! | AD30: =AD45/AD22 -> #DIV/0! | AE30: =AE45/AE22 -> #DIV/0! | AF30: =AF45/AF22 -> #DIV/0! | AG30: =AG45/AG22 -> #DIV/0! | AI30: =AI45/AI22 -> 59174.344 | AJ30: =AJ45/AJ22 -> 59174.344 | AK30: =AK45/AK22 -> 59174.344 | AL30: =AL45/AL22 -> 59174.344 | AM30: =AM45/AM22 -> 59174.344 | AN30: =AN45/AN22 -> 59174.344
A31: 10-100 млн | G31: =G46/G23 -> 35026.5 | H31: =H46/H23 -> 35026.5 | I31: =I46/I23 -> 35026.5 | J31: =J46/J23 -> 35026.5 | K31: =K46/K23 -> 35026.5 | N31: =N46/N23 -> 38183.395 | O31: =O46/O23 -> 38183.395 | P31: =P46/P23 -> 38183.395 | Q31: =Q46/Q23 -> 38183.395 | R31: =R46/R23 -> 38183.395 | T31: =T46/T23 -> 38183.395 | U31: =U46/U23 -> 38183.395 | V31: =V46/V23 -> 38183.395 | W31: =W46/W23 -> 38183.395 | X31: =X46/X23 -> 38183.395 | AC31: =AC46/AC23 -> #DIV/0! | AD31: =AD46/AD23 -> #DIV/0! | AE31: =AE46/AE23 -> #DIV/0! | AF31: =AF46/AF23 -> #DIV/0! | AG31: =AG46/AG23 -> #DIV/0! | AI31: =AI46/AI23 -> 38183.395 | AJ31: =AJ46/AJ23 -> 38183.395 | AK31: =AK46/AK23 -> 38183.395 | AL31: =AL46/AL23 -> 38183.395 | AM31: =AM46/AM23 -> 38183.395 | AN31: =AN46/AN23 -> 38183.395
A32: 1-10 млн | G32: =G47/G24 -> 23721.5 | H32: =H47/H24 -> 23721.5 | I32: =I47/I24 -> 23721.5 | J32: =J47/J24 -> 23721.5 | K32: =K47/K24 -> 23721.5 | N32: =N47/N24 -> 26600.988 | O32: =O47/O24 -> 26600.988 | P32: =P47/P24 -> 26600.988 | Q32: =Q47/Q24 -> 26600.988 | R32: =R47/R24 -> 26600.988 | T32: =T47/T24 -> 26600.988 | U32: =U47/U24 -> 26600.988 | V32: =V47/V24 -> 26600.988 | W32: =W47/W24 -> 26600.988 | X32: =X47/X24 -> 26600.988 | AC32: =AC47/AC24 -> #DIV/0! | AD32: =AD47/AD24 -> #DIV/0! | AE32: =AE47/AE24 -> #DIV/0! | AF32: =AF47/AF24 -> #DIV/0! | AG32: =AG47/AG24 -> #DIV/0! | AI32: =AI47/AI24 -> 26600.988 | AJ32: =AJ47/AJ24 -> 26600.988 | AK32: =AK47/AK24 -> 26600.988 | AL32: =AL47/AL24 -> 26600.988 | AM32: =AM47/AM24 -> 26600.988 | AN32: =AN47/AN24 -> 26600.988
A33: менее 1 млн | G33: =G48/G25 -> 20475.5 | H33: =H48/H25 -> 20475.5 | I33: =I48/I25 -> 20475.5 | J33: =J48/J25 -> 20475.5 | K33: =K48/K25 -> 20475.5 | N33: =N48/N25 -> 23361.309 | O33: =O48/O25 -> 23361.309 | P33: =P48/P25 -> 23361.309 | Q33: =Q48/Q25 -> 23361.309 | R33: =R48/R25 -> 23361.309 | T33: =T48/T25 -> 23361.309 | U33: =U48/U25 -> 23361.309 | V33: =V48/V25 -> 23361.309 | W33: =W48/W25 -> 23361.309 | X33: =X48/X25 -> 23361.309 | AC33: =AC48/AC25 -> 23361.309 | AD33: =AD48/AD25 -> 23361.309 | AE33: =AE48/AE25 -> 23361.309 | AF33: =AF48/AF25 -> 23361.309 | AG33: =AG48/AG25 -> 23361.309 | AI33: =AI48/AI25 -> #DIV/0! | AJ33: =AJ48/AJ25 -> #DIV/0! | AK33: =AK48/AK25 -> #DIV/0! | AL33: =AL48/AL25 -> #DIV/0! | AM33: =AM48/AM25 -> #DIV/0! | AN33: =AN48/AN25 -> 23361.309
A34: без оборотов
A35: Расходы на 1 платящего клиента | G35: =G36+G40+G41 -> 16968.269 | H35: =H36+H40+H41 -> 17023.901 | I35: =I36+I40+I41 -> 18076.805 | J35: =J36+J40+J41 -> 17504.01 | K35: =K36+K40+K41 -> 17017.946 | N35: =N50/N21 -> 10434.426 | O35: =O50/O21 -> 10478.531 | P35: =P50/P21 -> 11192.278 | Q35: =Q50/Q21 -> 10802.109 | R35: =R50/R21 -> 10470.138 | T35: =T50/T21 -> 4368.1181 | U35: =U50/U21 -> 4529.1226 | V35: =V50/V21 -> 8682.3067 | W35: =W50/W21 -> 6440.1063 | X35: =X50/X21 -> 4545.4564 | AC35: =AC50/AC21 -> 4340.9299 | AD35: =AD50/AD21 -> 4497.1845 | AE35: =AE50/AE21 -> 8693.1549 | AF35: =AF50/AF21 -> 6428.2867 | AG35: =AG50/AG21 -> 4514.5109 | AI35: =AI50/AI21 -> 10634.266 | AJ35: =AJ50/AJ21 -> 10679.22 | AK35: =AK50/AK21 -> 11351.547 | AL35: =AL50/AL21 -> 10985.584 | AM35: =AM50/AM21 -> 10674.654 | AN35: =AN50/AN21 -> 7379.6532
A36: CAC | G36: =SUM(G37:G39) -> 14126.766 | H36: =SUM(H37:H39) -> 14126.766 | I36: =SUM(I37:I39) -> 14126.766 | J36: =SUM(J37:J39) -> 14126.766 | K36: =SUM(K37:K39) -> 14126.766 | N36: =SUM(N37:N39) -> 9428.3828 | O36: =SUM(O37:O39) -> 9428.3828 | P36: =SUM(P37:P39) -> 9428.3828 | Q36: =SUM(Q37:Q39) -> 9428.3828 | R36: =SUM(R37:R39) -> 9428.3828 | T36: =SUM(T37:T39) -> 2844.9196 | U36: =SUM(U37:U39) -> 2844.9196 | V36: =SUM(V37:V39) -> 2844.9196 | W36: =SUM(W37:W39) -> 2844.9196 | X36: =SUM(X37:X39) -> 2844.9196 | AC36: =SUM(AC37:AC39) -> 2844.9196 | AD36: =SUM(AD37:AD39) -> 2844.9196 | AE36: =SUM(AE37:AE39) -> 2844.9196 | AF36: =SUM(AF37:AF39) -> 2844.9196 | AG36: =SUM(AG37:AG39) -> 2844.9196 | AI36: =SUM(AI37:AI39) -> 9428.3828 | AJ36: =SUM(AJ37:AJ39) -> 9428.3828 | AK36: =SUM(AK37:AK39) -> 9428.3828 | AL36: =SUM(AL37:AL39) -> 9428.3828 | AM36: =SUM(AM37:AM39) -> 9428.3828 | AN36: =AN51/AN21 -> 5726.1984
